Workbook
Name _C206: #REF!
Name _C207: #REF!
Name Bases: #REF!
Name DatosCompras: #REF!
Name Durations: #REF!
Name Fecha: #REF!
Name fecha2: #REF!
Name Filtros: #REF!
Name IQ_CH: 110000
Name IQ_CQ: 5000
Name IQ_CY: 10000
Name IQ_DAILY: 500000
Name IQ_FH: 100000
Name IQ_FQ: 500
Name IQ_FY: 1000
Name IQ_LTM: 2000
Name IQ_MONTH: 15000
Name IQ_NTM: 6000
Name IQ_WEEK: 50000
Name IQ_YTD: 3000
Name Nominales: #REF!
Name Pág1: #REF!
Name Pág2: #REF!
Name Portafolios: #REF!

Sheet Intro
B2: Grupo Coril
B3: Informe de Portafolios en Renta Variable
B5: Investment Team:
B7: Head of Investments:
F8: Victor Mendoza
F9: Portfolio Manager
F10: vmendoza@grupocoril.com
B12: Equity:
F13: Nabil Jarufe
F14: Analyst
F15: njarufe@grupocoril.com
B17: Fixed Income:
F18: Andru Ortega
F19: Assistant
F20: jortegar@grupocoril.com

Sheet Portada RV
B2: Grupo Coril
B3: Resumen de Rentabilidad en RV
B5: TC | C5: 3.7
B6: Fecha de Fin | C6: =+TODAY()-1 -> 46091
C8: Inversión | D8: P&L Total | E8: P&L Realizado | F8: P&L No Realizado | G8: Dividendos | H8: Retorno %
B9: PEN | C9: =+SUMIF(Stock!C:C,'Portada RV'!$B9,Stock!J:J) -> 2007058.2 | D9: =+SUMIF('P&L Total'!$C:$C,'Portada RV'!$B9,'P&L Total'!K:K) -> 440073.34 | E9: =+SUMIF(Ventas!E:E,'Portada RV'!B9,Ventas!L:L) -> 43711.25 | F9: =+D9-E9 -> 396362.09 | G9: =+SUMIF('P&L Total'!C:C,'Portada RV'!B9,'P&L Total'!I:I) -> 50329.098 | H9: =D9/C9 -> 0.21926287
B10: USD | C10: =+SUMIF(Stock!C:C,'Portada RV'!$B10,Stock!J:J) -> 6133797.7 | D10: =+SUMIF('P&L Total'!$C:$C,'Portada RV'!$B10,'P&L Total'!K:K) -> 129876.77 | E10: =+SUMIF(Ventas!E:E,'Portada RV'!B10,Ventas!L:L) -> 183413.15 | F10: =+D10-E10 -> -53536.383 | G10: =+SUMIF('P&L Total'!C:C,'Portada RV'!B10,'P&L Total'!I:I) -> 18849.479 | H10: =D10/C10 -> 0.021173957
C11: =+C10+C9/C5 -> 6676245.9 | E11: =+E10+E9/C5 -> 195227 | F11: =+F10+F9/3.7 -> 53588.505
B12: CxP PEN | C12: =+SUMIFS(Compras!L:L,Compras!O:O,"Pendiente",Compras!F:F,"PEN") -> 0
B13: CxC PEN | C13: =+SUMIFS(Ventas!J:J,Ventas!A:A,'Portada RV'!C6,Ventas!E:E,"PEN") -> 0
B14: CxP USD | C14: =+SUMIFS(Compras!L:L,Compras!O:O,"Pendiente",Compras!F:F,"USD") -> 99140.678
B15: CxC USD | C15: =+SUMIFS(Ventas!J:J,Ventas!A:A,'Portada RV'!C6,Ventas!E:E,"USD") -> 106656.37

Sheet P&L Total
A1: Stock | B1: Nombre | C1: Moneda | D1: Market price | E1: Stock inicial | F1: Stock final | G1: Compras | H1: Ventas | I1: Dividendos | J1: Valor stock final | K1: P&L Monto | L1: P&L %
A2: {=+_xlfn.UNIQUE(Tabla1[Identificador])} -> ITUB US Equity | B2: =+_xll.BDP($A2,"Name") -> ITAU UNIBANCO H-SPON PRF ADR | C2: =+INDEX(Tabla1[Moneda],MATCH('P&L Total'!A2,Tabla1[Identificador],0)) -> USD | D2: {=+IF(F2=0,"",_xll.BDP(A2,"PX_LAST"))} | E2: 0 | F2: =SUMIFS( Tabla1[Q], Tabla1[Identificador],A2, Tabla1[Stock],"stock" ) -> 0 | G2: =SUMIFS( Tabla1[Monto compra], Tabla1[Identificador],A2 ) -> 39868.251 | H2: =SUMIFS( Tabla2[Monto_venta], Tabla2[Identificador],A2 ) -> 46039.921 | I2: =+IFERROR(VLOOKUP(A2,Tabla3[[#All],[Identificador]:[Monto_mon_ins]],7,FALSE),"") -> 18.65535 | J2: =+IFERROR(D2*F2,"") | K2: =+IF(J2="",0,J2)-G2+H2+IF(I2="",0,I2) -> 6190.3244 | L2: =+K2/G2 -> 0.15526952
A3: EEM US Equity | B3: =+_xll.BDP($A3,"Name") -> ISHARES MSCI EMERGING MARKET | C3: =+INDEX(Tabla1[Moneda],MATCH('P&L Total'!A3,Tabla1[Identificador],0)) -> USD | D3: {=+IF(F3=0,"",_xll.BDP(A3,"PX_LAST"))} -> 58.68 | E3: 0 | F3: =SUMIFS( Tabla1[Q], Tabla1[Identificador],A3, Tabla1[Stock],"stock" ) -> 4425 | G3: =SUMIFS( Tabla1[Monto compra], Tabla1[Identificador],A3 ) -> 239499.39 | H3: =SUMIFS( Tabla2[Monto_venta], Tabla2[Identificador],A3 ) -> 0 | I3: =+IFERROR(VLOOKUP(A3,Tabla3[[#All],[Identificador]:[Monto_mon_ins]],7,FALSE),"") -> 3377.4255 | J3: =+IFERROR(D3*F3,"") -> 259659 | K3: =+IF(J3="",0,J3)-G3+H3+IF(I3="",0,I3) -> 23537.039 | L3: =+K3/G3 -> 0.098275989
A4: XLU US Equity | B4: =+_xll.BDP($A4,"Name") -> ST SR UTL SL SE SPDR ETF-USD | C4: =+INDEX(Tabla1[Moneda],MATCH('P&L Total'!A4,Tabla1[Identificador],0)) -> USD | D4: {=+IF(F4=0,"",_xll.BDP(A4,"PX_LAST"))} -> 46.56 | E4: 0 | F4: =SUMIFS( Tabla1[Q], Tabla1[Identificador],A4, Tabla1[Stock],"stock" ) -> 4123 | G4: =SUMIFS( Tabla1[Monto compra], Tabla1[Identificador],A4 ) -> 179688.62 | H4: =SUMIFS( Tabla2[Monto_venta], Tabla2[Identificador],A4 ) -> 0 | I4: =+IFERROR(VLOOKUP(A4,Tabla3[[#All],[Identificador]:[Monto_mon_ins]],7,FALSE),"") -> 531.4608 | J4: =+IFERROR(D4*F4,"") -> 191966.88 | K4: =+IF(J4="",0,J4)-G4+H4+IF(I4="",0,I4) -> 12809.723 | L4: =+K4/G4 -> 0.07128845
A5: XLI US Equity | B5: =+_xll.BDP($A5,"Name") -> SS INDUSTRIAL SELECT SECTOR | C5: =+INDEX(Tabla1[Moneda],MATCH('P&L Total'!A5,Tabla1[Identificador],0)) -> USD | D5: {=+IF(F5=0,"",_xll.BDP(A5,"PX_LAST"))} -> 170.02 | E5: 0 | F5: =SUMIFS( Tabla1[Q], Tabla1[Identificador],A5, Tabla1[Stock],"stock" ) -> 810 | G5: =SUMIFS( Tabla1[Monto compra], Tabla1[Identificador],A5 ) -> 129806.4 | H5: =SUMIFS( Tabla2[Monto_venta], Tabla2[Identificador],A5 ) -> 0 | I5: =+IFERROR(VLOOKUP(A5,Tabla3[[#All],[Identificador]:[Monto_mon_ins]],7,FALSE),"") -> 331.2748 | J5: =+IFERROR(D5*F5,"") -> 137716.2 | K5: =+IF(J5="",0,J5)-G5+H5+IF(I5="",0,I5) -> 8241.072 | L5: =+K5/G5 -> 0.063487408
A6: XLY US Equity | B6: =+_xll.BDP($A6,"Name") -> SS CONSUMER DISC SELECT SECT | C6: =+INDEX(Tabla1[Moneda],MATCH('P&L Total'!A6,Tabla1[Identificador],0)) -> USD | D6: {=+IF(F6=0,"",_xll.BDP(A6,"PX_LAST"))} -> 114.44 | E6: 0 | F6: =SUMIFS( Tabla1[Q], Tabla1[Identificador],A6, Tabla1[Stock],"stock" ) -> 1104 | G6: =SUMIFS( Tabla1[Monto compra], Tabla1[Identificador],A6 ) -> 129694.13 | H6: =SUMIFS( Tabla2[Monto_venta], Tabla2[Identificador],A6 ) -> 0 | I6: =+IFERROR(VLOOKUP(A6,Tabla3[[#All],[Identificador]:[Monto_mon_ins]],7,FALSE),"") -> 142.5425 | J6: =+IFERROR(D6*F6,"") -> 126341.76 | K6: =+IF(J6="",0,J6)-G6+H6+IF(I6="",0,I6) -> -3209.8275 | L6: =+K6/G6 -> -0.024749212
A7: PLTR US Equity | B7: =+_xll.BDP($A7,"Name") -> PALANTIR TECHNOLOGIES INC-A | C7: =+INDEX(Tabla1[Moneda],MATCH('P&L Total'!A7,Tabla1[Identificador],0)) -> USD | D7: {=+IF(F7=0,"",_xll.BDP(A7,"PX_LAST"))} | E7: 0 | F7: =SUMIFS( Tabla1[Q], Tabla1[Identificador],A7, Tabla1[Stock],"stock" ) -> 0 | G7: =SUMIFS( Tabla1[Monto compra], Tabla1[Identificador],A7 ) -> 887987.62 | H7: =SUMIFS( Tabla2[Monto_venta], Tabla2[Identificador],A7 ) -> 930751.55 | I7: =+IFERROR(VLOOKUP(A7,Tabla3[[#All],[Identificador]:[Monto_mon_ins]],7,FALSE),"") | J7: =+IFERROR(D7*F7,"") | K7: =+IF(J7="",0,J7)-G7+H7+IF(I7="",0,I7) -> 42763.93 | L7: =+K7/G7 -> 0.048158251
A8: SPY US Equity | B8: =+_xll.BDP($A8,"Name") -> SS SPDR S&P 500 ETF TRUST-US | C8: =+INDEX(Tabla1[Moneda],MATCH('P&L Total'!A8,Tabla1[Identificador],0)) -> USD | D8: {=+IF(F8=0,"",_xll.BDP(A8,"PX_LAST"))} | E8: 0 | F8: =SUMIFS( Tabla1[Q], Tabla1[Identificador],A8, Tabla1[Stock],"stock" ) -> 0 | G8: =SUMIFS( Tabla1[Monto compra], Tabla1[Identificador],A8 ) -> 208990.9 | H8: =SUMIFS( Tabla2[Monto_venta], Tabla2[Identificador],A8 ) -> 216710.2 | I8: =+IFERROR(VLOOKUP(A8,Tabla3[[#All],[Identificador]:[Monto_mon_ins]],7,FALSE),"") | J8: =+IFERROR(D8*F8,"") | K8: =+IF(J8="",0,J8)-G8+H8+IF(I8="",0,I8) -> 7719.291 | L8: =+K8/G8 -> 0.036936014
A9: FDX US Equity | B9: =+_xll.BDP($A9,"Name") -> FEDEX CORP | C9: =+INDEX(Tabla1[Moneda],MATCH('P&L Total'!A9,Tabla1[Identificador],0)) -> USD | D9: {=+IF(F9=0,"",_xll.BDP(A9,"PX_LAST"))} -> 359.47 | E9: 0 | F9: =SUMIFS( Tabla1[Q], Tabla1[Identificador],A9, Tabla1[Stock],"stock" ) -> 218 | G9: =SUMIFS( Tabla1[Monto compra], Tabla1[Identificador],A9 ) -> 49791.2 | H9: =SUMIFS( Tabla2[Monto_venta], Tabla2[Identificador],A9 ) -> 0 | I9: =+IFERROR(VLOOKUP(A9,Tabla3[[#All],[Identificador]:[Monto_mon_ins]],7,FALSE),"") -> 316.1 | J9: =+IFERROR(D9*F9,"") -> 78364.46 | K9: =+IF(J9="",0,J9)-G9+H9+IF(I9="",0,I9) -> 28889.36 | L9: =+K9/G9 -> 0.58021016
A10: XPEV US Equity | B10: =+_xll.BDP($A10,"Name") -> XPENG INC - ADR | C10: =+INDEX(Tabla1[Moneda],MATCH('P&L Total'!A10,Tabla1[Identificador],0)) -> USD | D10: {=+IF(F10=0,"",_xll.BDP(A10,"PX_LAST"))} | E10: 0 | F10: =SUMIFS( Tabla1[Q], Tabla1[Identificador],A10, Tabla1[Stock],"stock" ) -> 0 | G10: =SUMIFS( Tabla1[Monto compra], Tabla1[Identificador],A10 ) -> 54893.432 | H10: =SUMIFS( Tabla2[Monto_venta], Tabla2[Identificador],A10 ) -> 69350 | I10: =+IFERROR(VLOOKUP(A10,Tabla3[[#All],[Identificador]:[Monto_mon_ins]],7,FALSE),"") | J10: =+IFERROR(D10*F10,"") | K10: =+IF(J10="",0,J10)-G10+H10+IF(I10="",0,I10) -> 14456.568 | L10: =+K10/G10 -> 0.26335696
A11: EWP US Equity | B11: =+_xll.BDP($A11,"Name") -> ISHARES MSCI SPAIN ETF | C11: =+INDEX(Tabla1[Moneda],MATCH('P&L Total'!A11,Tabla1[Identificador],0)) -> USD | D11: {=+IF(F11=0,"",_xll.BDP(A11,"PX_LAST"))} | E11: 0 | F11: =SUMIFS( Tabla1[Q], Tabla1[Identificador],A11, Tabla1[Stock],"stock" ) -> 0 | G11: =SUMIFS( Tabla1[Monto compra], Tabla1[Identificador],A11 ) -> 49907.71 | H11: =SUMIFS( Tabla2[Monto_venta], Tabla2[Identificador],A11 ) -> 56736.033 | I11: =+IFERROR(VLOOKUP(A11,Tabla3[[#All],[Identificador]:[Monto_mon_ins]],7,FALSE),"") -> 763.32147 | J11: =+IFERROR(D11*F11,"") | K11: =+IF(J11="",0,J11)-G11+H11+IF(I11="",0,I11) -> 7591.6448 | L11: =+K11/G11 -> 0.15211367
A12: NIO US Equity | B12: =+_xll.BDP($A12,"Name") -> NIO INC - ADR | C12: =+INDEX(Tabla1[Moneda],MATCH('P&L Total'!A12,Tabla1[Identificador],0)) -> USD | D12: {=+IF(F12=0,"",_xll.BDP(A12,"PX_LAST"))} -> 5.7 | E12: 0 | F12: =SUMIFS( Tabla1[Q], Tabla1[Identificador],A12, Tabla1[Stock],"stock" ) -> 18368 | G12: =SUMIFS( Tabla1[Monto compra], Tabla1[Identificador],A12 ) -> 104519.95 | H12: =SUMIFS( Tabla2[Monto_venta], Tabla2[Identificador],A12 ) -> 0 | I12: =+IFERROR(VLOOKUP(A12,Tabla3[[#All],[Identificador]:[Monto_mon_ins]],7,FALSE),"") | J12: =+IFERROR(D12*F12,"") -> 104697.6 | K12: =+IF(J12="",0,J12)-G12+H12+IF(I12="",0,I12) -> 177.648 | L12: =+K12/G12 -> 0.0016996563
A13: PRU US Equity | B13: =+_xll.BDP($A13,"Name") -> PRUDENTIAL FINANCIAL INC | C13: =+INDEX(Tabla1[Moneda],MATCH('P&L Total'!A13,Tabla1[Identificador],0)) -> USD | D13: {=+IF(F13=0,"",_xll.BDP(A13,"PX_LAST"))} -> 95.47 | E13: 0 | F13: =SUMIFS( Tabla1[Q], Tabla1[Identificador],A13, Tabla1[Stock],"stock" ) -> 483 | G13: =SUMIFS( Tabla1[Monto compra], Tabla1[Identificador],A13 ) -> 49924.088 | H13: =SUMIFS( Tabla2[Monto_venta], Tabla2[Identificador],A13 ) -> 0 | I13: =+IFERROR(VLOOKUP(A13,Tabla3[[#All],[Identificador]:[Monto_mon_ins]],7,FALSE),"") -> 652.05 | J13: =+IFERROR(D13*F13,"") -> 46112.01 | K13: =+IF(J13="",0,J13)-G13+H13+IF(I13="",0,I13) -> -3160.0275 | L13: =+K13/G13 -> -0.06329665
A14: KMB US Equity | B14: =+_xll.BDP($A14,"Name") -> KIMBERLY-CLARK CORP | C14: =+INDEX(Tabla1[Moneda],MATCH('P&L Total'!A14,Tabla1[Identificador],0)) -> USD | D14: {=+IF(F14=0,"",_xll.BDP(A14,"PX_LAST"))} -> 101.71 | E14: 0 | F14: =SUMIFS( Tabla1[Q], Tabla1[Identificador],A14, Tabla1[Stock],"stock" ) -> 802 | G14: =SUMIFS( Tabla1[Monto compra], Tabla1[Identificador],A14 ) -> 91600.34 | H14: =SUMIFS( Tabla2[Monto_venta], Tabla2[Identificador],A14 ) -> 0 | I14: =+IFERROR(VLOOKUP(A14,Tabla3[[#All],[Identificador]:[Monto_mon_ins]],7,FALSE),"") -> 506.52 | J14: =+IFERROR(D14*F14,"") -> 81571.42 | K14: =+IF(J14="",0,J14)-G14+H14+IF(I14="",0,I14) -> -9522.3998 | L14: =+K14/G14 -> -0.10395594
... A58: EPU US Equity | B58: =+_xll.BDP($A58,"Name") -> ISHARES MSCI PERU AND GLOBAL | C58: =+INDEX(Tabla1[Moneda],MATCH('P&L Total'!A58,Tabla1[Identificador],0)) -> USD | D58: {=+IF(F58=0,"",_xll.BDP(A58,"PX_LAST"))} -> 86.87 | E58: 0 | F58: =SUMIFS( Tabla1[Q], Tabla1[Identificador],A58, Tabla1[Stock],"stock" ) -> 2369 | G58: =SUMIFS( Tabla1[Monto compra], Tabla1[Identificador],A58 ) -> 198753.77 | H58: =SUMIFS( Tabla2[Monto_venta], Tabla2[Identificador],A58 ) -> 0 | I58: =+IFERROR(VLOOKUP(A58,Tabla3[[#All],[Identificador]:[Monto_mon_ins]],7,FALSE),"") | J58: =+IFERROR(D58*F58,"") -> 205795.03 | K58: =+IF(J58="",0,J58)-G58+H58+IF(I58="",0,I58) -> 7041.2579 | L58: =+K58/G58 -> 0.03542704

Sheet Stock
A1: Stock | B1: ISIN | C1: Moneda | D1: Security Type | E1: Nombre | F1: Q | G1: Precio Promedio C | H1: P mercado | I1: P Anterior | J1: Monto compra | K1: Monto actual | L1: Monto Anterior | M1: % Allocation | N1: P&L % | O1: P&L 1d
A2: {=+_xlfn.UNIQUE(_xlfn._xlws.FILTER(Tabla1[Identificador],(Tabla1[Stock]="stock"),))} -> EEM US Equity | B2: {=_xll.BDP(A2,"ID_ISIN")} -> US4642872349 | C2: =+INDEX(Tabla1[Moneda],MATCH(A2,Tabla1[Identificador],0)) -> USD | D2: {=_xll.BDP(A2, "DS213")} -> ETP | E2: =+_xll.BDP($A2,"Name") -> ISHARES MSCI EMERGING MARKET | F2: =SUMIFS( Tabla1[Q], Tabla1[Identificador],A2, Tabla1[Stock],"stock" ) -> 4425 | G2: {=SUMPRODUCT( (Tabla1[Identificador]=A2)* (Tabla1[Stock]="stock")* Tabla1[Q]* Tabla1[P] ) /SUMIFS( Tabla1[Q], Tabla1[Identificador],A2, Tabla1[Stock],"stock" )} -> 54.124155 | H2: {=+_xll.BDP(A2,"PX_LAST")} -> 58.68 | I2: {=+_xll.BDP(A2,"PX_CLOSE_1D")} -> 58.45 | J2: =+F2*G2 -> 239499.39 | K2: =+H2*F2 -> 259659 | L2: =+I2*F2 -> 258641.25 | M2: =+IF(C2="USD",K2/SUMIF(C:C,C2,K:K),K2/SUMIF(C:C,C2,K:K)) -> 0.042838039 | N2: =+(H2*F2)/(F2*G2)-1 -> 0.084173968 | O2: {=+_xll.BDP(A2,"CURRENT_TRR_1D")/100} -> 0
A3: XLU US Equity | B3: {=_xll.BDP(A3,"ID_ISIN")} -> US81369Y8865 | C3: =+INDEX(Tabla1[Moneda],MATCH(A3,Tabla1[Identificador],0)) -> USD | D3: {=_xll.BDP(A3, "DS213")} -> ETP | E3: =+_xll.BDP($A3,"Name") -> ST SR UTL SL SE SPDR ETF-USD | F3: =SUMIFS( Tabla1[Q], Tabla1[Identificador],A3, Tabla1[Stock],"stock" ) -> 4123 | G3: {=SUMPRODUCT( (Tabla1[Identificador]=A3)* (Tabla1[Stock]="stock")* Tabla1[Q]* Tabla1[P] ) /SUMIFS( Tabla1[Q], Tabla1[Identificador],A3, Tabla1[Stock],"stock" )} -> 43.582008 | H3: {=+_xll.BDP(A3,"PX_LAST")} -> 46.56 | I3: {=+_xll.BDP(A3,"PX_CLOSE_1D")} -> 46.85 | J3: =+F3*G3 -> 179688.62 | K3: =+H3*F3 -> 191966.88 | L3: =+I3*F3 -> 193162.55 | M3: =+IF(C3="USD",K3/SUMIF(C:C,C3,K:K),K3/SUMIF(C:C,C3,K:K)) -> 0.031670324 | N3: =+(H3*F3)/(F3*G3)-1 -> 0.068330774 | O3: {=+_xll.BDP(A3,"CURRENT_TRR_1D")/100} -> 0
A4: XLI US Equity | B4: {=_xll.BDP(A4,"ID_ISIN")} -> US81369Y7040 | C4: =+INDEX(Tabla1[Moneda],MATCH(A4,Tabla1[Identificador],0)) -> USD | D4: {=_xll.BDP(A4, "DS213")} -> ETP | E4: =+_xll.BDP($A4,"Name") -> SS INDUSTRIAL SELECT SECTOR | F4: =SUMIFS( Tabla1[Q], Tabla1[Identificador],A4, Tabla1[Stock],"stock" ) -> 810 | G4: {=SUMPRODUCT( (Tabla1[Identificador]=A4)* (Tabla1[Stock]="stock")* Tabla1[Q]* Tabla1[P] ) /SUMIFS( Tabla1[Q], Tabla1[Identificador],A4, Tabla1[Stock],"stock" )} -> 160.25482 | H4: {=+_xll.BDP(A4,"PX_LAST")} -> 170.02 | I4: {=+_xll.BDP(A4,"PX_CLOSE_1D")} -> 170.94 | J4: =+F4*G4 -> 129806.4 | K4: =+H4*F4 -> 137716.2 | L4: =+I4*F4 -> 138461.4 | M4: =+IF(C4="USD",K4/SUMIF(C:C,C4,K:K),K4/SUMIF(C:C,C4,K:K)) -> 0.022720152 | N4: =+(H4*F4)/(F4*G4)-1 -> 0.060935339 | O4: {=+_xll.BDP(A4,"CURRENT_TRR_1D")/100} -> 0
A5: XLY US Equity | B5: {=_xll.BDP(A5,"ID_ISIN")} -> US81369Y4070 | C5: =+INDEX(Tabla1[Moneda],MATCH(A5,Tabla1[Identificador],0)) -> USD | D5: {=_xll.BDP(A5, "DS213")} -> ETP | E5: =+_xll.BDP($A5,"Name") -> SS CONSUMER DISC SELECT SECT | F5: =SUMIFS( Tabla1[Q], Tabla1[Identificador],A5, Tabla1[Stock],"stock" ) -> 1104 | G5: {=SUMPRODUCT( (Tabla1[Identificador]=A5)* (Tabla1[Stock]="stock")* Tabla1[Q]* Tabla1[P] ) /SUMIFS( Tabla1[Q], Tabla1[Identificador],A5, Tabla1[Stock],"stock" )} -> 117.47657 | H5: {=+_xll.BDP(A5,"PX_LAST")} -> 114.44 | I5: {=+_xll.BDP(A5,"PX_CLOSE_1D")} -> 114.59 | J5: =+F5*G5 -> 129694.13 | K5: =+H5*F5 -> 126341.76 | L5: =+I5*F5 -> 126507.36 | M5: =+IF(C5="USD",K5/SUMIF(C:C,C5,K:K),K5/SUMIF(C:C,C5,K:K)) -> 0.020843619 | N5: =+(H5*F5)/(F5*G5)-1 -> -0.025848279 | O5: {=+_xll.BDP(A5,"CURRENT_TRR_1D")/100} -> 0
A6: FDX US Equity | B6: {=_xll.BDP(A6,"ID_ISIN")} -> US31428X1063 | C6: =+INDEX(Tabla1[Moneda],MATCH(A6,Tabla1[Identificador],0)) -> USD | D6: {=_xll.BDP(A6, "DS213")} -> Common Stock | E6: =+_xll.BDP($A6,"Name") -> FEDEX CORP | F6: =SUMIFS( Tabla1[Q], Tabla1[Identificador],A6, Tabla1[Stock],"stock" ) -> 218 | G6: {=SUMPRODUCT( (Tabla1[Identificador]=A6)* (Tabla1[Stock]="stock")* Tabla1[Q]* Tabla1[P] ) /SUMIFS( Tabla1[Q], Tabla1[Identificador],A6, Tabla1[Stock],"stock" )} -> 228.4 | H6: {=+_xll.BDP(A6,"PX_LAST")} -> 359.47 | I6: {=+_xll.BDP(A6,"PX_CLOSE_1D")} -> 361.1 | J6: =+F6*G6 -> 49791.2 | K6: =+H6*F6 -> 78364.46 | L6: =+I6*F6 -> 78719.8 | M6: =+IF(C6="USD",K6/SUMIF(C:C,C6,K:K),K6/SUMIF(C:C,C6,K:K)) -> 0.012928417 | N6: =+(H6*F6)/(F6*G6)-1 -> 0.57386165 | O6: {=+_xll.BDP(A6,"CURRENT_TRR_1D")/100} -> 0
A7: NIO US Equity | B7: {=_xll.BDP(A7,"ID_ISIN")} -> US62914V1061 | C7: =+INDEX(Tabla1[Moneda],MATCH(A7,Tabla1[Identificador],0)) -> USD | D7: {=_xll.BDP(A7, "DS213")} -> ADR | E7: =+_xll.BDP($A7,"Name") -> NIO INC - ADR | F7: =SUMIFS( Tabla1[Q], Tabla1[Identificador],A7, Tabla1[Stock],"stock" ) -> 18368 | G7: {=SUMPRODUCT( (Tabla1[Identificador]=A7)* (Tabla1[Stock]="stock")* Tabla1[Q]* Tabla1[P] ) /SUMIFS( Tabla1[Q], Tabla1[Identificador],A7, Tabla1[Stock],"stock" )} -> 5.6903284 | H7: {=+_xll.BDP(A7,"PX_LAST")} -> 5.7 | I7: {=+_xll.BDP(A7,"PX_CLOSE_1D")} -> 4.94 | J7: =+F7*G7 -> 104519.95 | K7: =+H7*F7 -> 104697.6 | L7: =+I7*F7 -> 90737.92 | M7: =+IF(C7="USD",K7/SUMIF(C:C,C7,K:K),K7/SUMIF(C:C,C7,K:K)) -> 0.017272807 | N7: =+(H7*F7)/(F7*G7)-1 -> 0.0016996563 | O7: {=+_xll.BDP(A7,"CURRENT_TRR_1D")/100} -> 0
A8: PRU US Equity | B8: {=_xll.BDP(A8,"ID_ISIN")} -> US7443201022 | C8: =+INDEX(Tabla1[Moneda],MATCH(A8,Tabla1[Identificador],0)) -> USD | D8: {=_xll.BDP(A8, "DS213")} -> Common Stock | E8: =+_xll.BDP($A8,"Name") -> PRUDENTIAL FINANCIAL INC | F8: =SUMIFS( Tabla1[Q], Tabla1[Identificador],A8, Tabla1[Stock],"stock" ) -> 483 | G8: {=SUMPRODUCT( (Tabla1[Identificador]=A8)* (Tabla1[Stock]="stock")* Tabla1[Q]* Tabla1[P] ) /SUMIFS( Tabla1[Q], Tabla1[Identificador],A8, Tabla1[Stock],"stock" )} -> 103.3625 | H8: {=+_xll.BDP(A8,"PX_LAST")} -> 95.47 | I8: {=+_xll.BDP(A8,"PX_CLOSE_1D")} -> 95.93 | J8: =+F8*G8 -> 49924.088 | K8: =+H8*F8 -> 46112.01 | L8: =+I8*F8 -> 46334.19 | M8: =+IF(C8="USD",K8/SUMIF(C:C,C8,K:K),K8/SUMIF(C:C,C8,K:K)) -> 0.0076074702 | N8: =+(H8*F8)/(F8*G8)-1 -> -0.07635748 | O8: {=+_xll.BDP(A8,"CURRENT_TRR_1D")/100} -> 0
A9: KMB US Equity | B9: {=_xll.BDP(A9,"ID_ISIN")} -> US4943681035 | C9: =+INDEX(Tabla1[Moneda],MATCH(A9,Tabla1[Identificador],0)) -> USD | D9: {=_xll.BDP(A9, "DS213")} -> Common Stock | E9: =+_xll.BDP($A9,"Name") -> KIMBERLY-CLARK CORP | F9: =SUMIFS( Tabla1[Q], Tabla1[Identificador],A9, Tabla1[Stock],"stock" ) -> 802 | G9: {=SUMPRODUCT( (Tabla1[Identificador]=A9)* (Tabla1[Stock]="stock")* Tabla1[Q]* Tabla1[P] ) /SUMIFS( Tabla1[Q], Tabla1[Identificador],A9, Tabla1[Stock],"stock" )} -> 114.21489 | H9: {=+_xll.BDP(A9,"PX_LAST")} -> 101.71 | I9: {=+_xll.BDP(A9,"PX_CLOSE_1D")} -> 102.85 | J9: =+F9*G9 -> 91600.34 | K9: =+H9*F9 -> 81571.42 | L9: =+I9*F9 -> 82485.7 | M9: =+IF(C9="USD",K9/SUMIF(C:C,C9,K:K),K9/SUMIF(C:C,C9,K:K)) -> 0.013457495 | N9: =+(H9*F9)/(F9*G9)-1 -> -0.10948562 | O9: {=+_xll.BDP(A9,"CURRENT_TRR_1D")/100} -> 0
A10: UNH US Equity | B10: {=_xll.BDP(A10,"ID_ISIN")} -> US91324P1021 | C10: =+INDEX(Tabla1[Moneda],MATCH(A10,Tabla1[Identificador],0)) -> USD | D10: {=_xll.BDP(A10, "DS213")} -> Common Stock | E10: =+_xll.BDP($A10,"Name") -> UNITEDHEALTH GROUP INC | F10: =SUMIFS( Tabla1[Q], Tabla1[Identificador],A10, Tabla1[Stock],"stock" ) -> 437 | G10: {=SUMPRODUCT( (Tabla1[Identificador]=A10)* (Tabla1[Stock]="stock")* Tabla1[Q]* Tabla1[P] ) /SUMIFS( Tabla1[Q], Tabla1[Identificador],A10, Tabla1[Stock],"stock" )} -> 342.35101 | H10: {=+_xll.BDP(A10,"PX_LAST")} -> 282.34 | I10: {=+_xll.BDP(A10,"PX_CLOSE_1D")} -> 285.17 | J10: =+F10*G10 -> 149607.39 | K10: =+H10*F10 -> 123382.58 | L10: =+I10*F10 -> 124619.29 | M10: =+IF(C10="USD",K10/SUMIF(C:C,C10,K:K),K10/SUMIF(C:C,C10,K:K)) -> 0.020355419 | N10: =+(H10*F10)/(F10*G10)-1 -> -0.17529089 | O10: {=+_xll.BDP(A10,"CURRENT_TRR_1D")/100} -> 0
A11: KKR US Equity | B11: {=_xll.BDP(A11,"ID_ISIN")} -> US48251W1045 | C11: =+INDEX(Tabla1[Moneda],MATCH(A11,Tabla1[Identificador],0)) -> USD | D11: {=_xll.BDP(A11, "DS213")} -> Common Stock | E11: =+_xll.BDP($A11,"Name") -> KKR & CO INC | F11: =SUMIFS( Tabla1[Q], Tabla1[Identificador],A11, Tabla1[Stock],"stock" ) -> 341 | G11: {=SUMPRODUCT( (Tabla1[Identificador]=A11)* (Tabla1[Stock]="stock")* Tabla1[Q]* Tabla1[P] ) /SUMIFS( Tabla1[Q], Tabla1[Identificador],A11, Tabla1[Stock],"stock" )} -> 146.35 | H11: {=+_xll.BDP(A11,"PX_LAST")} -> 89.96 | I11: {=+_xll.BDP(A11,"PX_CLOSE_1D")} -> 90.94 | J11: =+F11*G11 -> 49905.35 | K11: =+H11*F11 -> 30676.36 | L11: =+I11*F11 -> 31010.54 | M11: =+IF(C11="USD",K11/SUMIF(C:C,C11,K:K),K11/SUMIF(C:C,C11,K:K)) -> 0.0050609265 | N11: =+(H11*F11)/(F11*G11)-1 -> -0.38530919 | O11: {=+_xll.BDP(A11,"CURRENT_TRR_1D")/100} -> 0
A12: EUFN US Equity | B12: {=_xll.BDP(A12,"ID_ISIN")} -> US4642891802 | C12: =+INDEX(Tabla1[Moneda],MATCH(A12,Tabla1[Identificador],0)) -> USD | D12: {=_xll.BDP(A12, "DS213")} -> ETP | E12: =+_xll.BDP($A12,"Name") -> ISHARES MSCI EUROPE FINANCIA | F12: =SUMIFS( Tabla1[Q], Tabla1[Identificador],A12, Tabla1[Stock],"stock" ) -> 4135 | G12: {=SUMPRODUCT( (Tabla1[Identificador]=A12)* (Tabla1[Stock]="stock")* Tabla1[Q]* Tabla1[P] ) /SUMIFS( Tabla1[Q], Tabla1[Identificador],A12, Tabla1[Stock],"stock" )} -> 33.794264 | H12: {=+_xll.BDP(A12,"PX_LAST")} -> 35.24 | I12: {=+_xll.BDP(A12,"PX_CLOSE_1D")} -> 35.2 | J12: =+F12*G12 -> 139739.28 | K12: =+H12*F12 -> 145717.4 | L12: =+I12*F12 -> 145552 | M12: =+IF(C12="USD",K12/SUMIF(C:C,C12,K:K),K12/SUMIF(C:C,C12,K:K)) -> 0.024040175 | N12: =+(H12*F12)/(F12*G12)-1 -> 0.042780512 | O12: {=+_xll.BDP(A12,"CURRENT_TRR_1D")/100} -> 0
A13: EZU US Equity | B13: {=_xll.BDP(A13,"ID_ISIN")} -> US4642866085 | C13: =+INDEX(Tabla1[Moneda],MATCH(A13,Tabla1[Identificador],0)) -> USD | D13: {=_xll.BDP(A13, "DS213")} -> ETP | E13: =+_xll.BDP($A13,"Name") -> ISHARES MSCI EUROZONE ETF | F13: =SUMIFS( Tabla1[Q], Tabla1[Identificador],A13, Tabla1[Stock],"stock" ) -> 2391 | G13: {=SUMPRODUCT( (Tabla1[Identificador]=A13)* (Tabla1[Stock]="stock")* Tabla1[Q]* Tabla1[P] ) /SUMIFS( Tabla1[Q], Tabla1[Identificador],A13, Tabla1[Stock],"stock" )} -> 62.629001 | H13: {=+_xll.BDP(A13,"PX_LAST")} -> 64.04 | I13: {=+_xll.BDP(A13,"PX_CLOSE_1D")} -> 63.87 | J13: =+F13*G13 -> 149745.94 | K13: =+H13*F13 -> 153119.64 | L13: =+I13*F13 -> 152713.17 | M13: =+IF(C13="USD",K13/SUMIF(C:C,C13,K:K),K13/SUMIF(C:C,C13,K:K)) -> 0.025261382 | N13: =+(H13*F13)/(F13*G13)-1 -> 0.022529476 | O13: {=+_xll.BDP(A13,"CURRENT_TRR_1D")/100} -> 0
A14: FERREYC1 pe Equity | B14: {=_xll.BDP(A14,"ID_ISIN")} -> PEP736001004 | C14: =+INDEX(Tabla1[Moneda],MATCH(A14,Tabla1[Identificador],0)) -> PEN | D14: {=_xll.BDP(A14, "DS213")} -> Common Stock | E14: =+_xll.BDP($A14,"Name") -> FERREYCORP SAA | F14: =SUMIFS( Tabla1[Q], Tabla1[Identificador],A14, Tabla1[Stock],"stock" ) -> 103492 | G14: {=SUMPRODUCT( (Tabla1[Identificador]=A14)* (Tabla1[Stock]="stock")* Tabla1[Q]* Tabla1[P] ) /SUMIFS( Tabla1[Q], Tabla1[Identificador],A14, Tabla1[Stock],"stock" )} -> 3.3176217 | H14: {=+_xll.BDP(A14,"PX_LAST")} -> 4.1 | I14: {=+_xll.BDP(A14,"PX_CLOSE_1D")} -> 4.05 | J14: =+F14*G14 -> 343347.3 | K14: =+H14*F14 -> 424317.2 | L14: =+I14*F14 -> 419142.6 | M14: =+IF(C14="USD",K14/SUMIF(C:C,C14,K:K),K14/SUMIF(C:C,C14,K:K)) -> 0.18032331 | N14: =+(H14*F14)/(F14*G14)-1 -> 0.23582507 | O14: {=+_xll.BDP(A14,"CURRENT_TRR_1D")/100} -> 0
... A49: EPU US Equity | B49: {=_xll.BDP(A49,"ID_ISIN")} -> US4642898427 | C49: =+INDEX(Tabla1[Moneda],MATCH(A49,Tabla1[Identificador],0)) -> USD | D49: {=_xll.BDP(A49, "DS213")} -> ETP | E49: =+_xll.BDP($A49,"Name") -> ISHARES MSCI PERU AND GLOBAL | F49: =SUMIFS( Tabla1[Q], Tabla1[Identificador],A49, Tabla1[Stock],"stock" ) -> 2369 | G49: {=SUMPRODUCT( (Tabla1[Identificador]=A49)* (Tabla1[Stock]="stock")* Tabla1[Q]* Tabla1[P] ) /SUMIFS( Tabla1[Q], Tabla1[Identificador],A49, Tabla1[Stock],"stock" )} -> 83.897751 | H49: {=+_xll.BDP(A49,"PX_LAST")} -> 86.87 | I49: {=+_xll.BDP(A49,"PX_CLOSE_1D")} -> 83.97 | J49: =+F49*G49 -> 198753.77 | K49: =+H49*F49 -> 205795.03 | L49: =+I49*F49 -> 198924.93 | M49: =+IF(C49="USD",K49/SUMIF(C:C,C49,K:K),K49/SUMIF(C:C,C49,K:K)) -> 0.033951666 | N49: =+(H49*F49)/(F49*G49)-1 -> 0.03542704 | O49: {=+_xll.BDP(A49,"CURRENT_TRR_1D")/100} -> 0

Sheet DATA
C2: FDX | D2: MINSURI1 | E2: SIDERC1 | F2: ORYGENC1 | G2: XPEV | H2: FERREYC1 | I2: TAN | J2: ITUB | K2: EWP | L2: EEM | M2: BAP | N2: EUFN | O2: EWZ | P2: ICLN | Q2: PFE | R2: BVN | S2: XLI | T2: EZU | U2: BIDU | V2: XLU | W2: PLTR | X2: EWL | Y2: EWQ | Z2: SMH | AA2: VOLCABC1 | AB2: INRETC1 | AC2: JAVA | AD2: SPY | AE2: CPACASC1 | AF2: JDOC | AG2: EWZS | AH2: QQQ | AI2: PRU | AJ2: DIS | AK2: XLY | AL2: AMZN | AM2: TQQQ | AN2: TCHI | AO2: CQQQ | AP2: AUNA | AQ2: KMB | AR2: CIB | AS2: NFLX | AT2: NIO | AU2: UNH | AV2: TTWO | AW2: KKR
B3: 45901 | C3: #N/A N/A | D3: 3.98 | E3: 1.76 | F3: 2.55 | G3: #N/A N/A | H3: 3.49 | I3: #N/A N/A | J3: #N/A N/A | K3: #N/A N/A | L3: #N/A N/A | M3: #N/A N/A | N3: #N/A N/A | O3: #N/A N/A | P3: #N/A N/A | Q3: #N/A N/A | R3: #N/A N/A | S3: #N/A N/A | T3: #N/A N/A | U3: #N/A N/A | V3: #N/A N/A | W3: #N/A N/A | X3: #N/A N/A | Y3: #N/A N/A | Z3: #N/A N/A | AA3: 0.376 | AB3: 27.5 | AC3: #N/A N/A | AD3: #N/A N/A | AE3: 4.61 | AF3: #N/A N/A | AG3: #N/A N/A | AH3: #N/A N/A | AI3: #N/A N/A | AJ3: #N/A N/A | AK3: #N/A N/A | AL3: #N/A N/A | AM3: #N/A N/A | AN3: #N/A N/A | AO3: #N/A N/A | AP3: #N/A N/A | AQ3: #N/A N/A | AR3: #N/A N/A | AS3: #N/A N/A | AT3: #N/A N/A | AU3: #N/A N/A | AV3: #N/A N/A | AW3: #N/A N/A
B4: 45902 | C4: 224.18 | D4: 3.99 | E4: 1.74 | F4: 2.55 | G4: 20.79 | H4: 3.47 | I4: 40.98 | J4: 6.8058 | K4: 47.02 | L4: 49.82 | M4: 260.11 | N4: 32.97 | O4: 29 | P4: 14.16 | Q4: 24.98 | R4: 19.64 | S4: 150.56 | T4: 59.035 | U4: 96.29 | V4: 42.02 | W4: 157.09 | X4: 54.67 | Y4: 42.29 | Z4: 286.48 | AA4: 0.384 | AB4: 27.94 | AC4: 67.81 | AD4: 640.27 | AE4: 4.73 | AF4: 51.593 | AG4: 13.1551 | AH4: 565.62 | AI4: 107.41 | AJ4: 118.27 | AK4: 115.005 | AL4: 225.34 | AM4: 43.54 | AN4: 23.51 | AO4: 52.31 | AP4: 6.33 | AQ4: 128.84 | AR4: 49.88 | AS4: 121.411 | AT4: 6.58 | AU4: 308.8 | AV4: 240.95 | AW4: 138.74
B5: 45903 | C5: 225.34 | D5: 4 | E5: 1.66 | F5: 2.56 | G5: 20.25 | H5: 3.48 | I5: 41.57 | J5: 6.7379 | K5: 47.05 | L5: 50.01 | M5: 261.56 | N5: 32.99 | O5: 28.99 | P5: 14.2 | Q5: 24.79 | R5: 19.94 | S5: 149.8 | T5: 59.15 | U5: 96.4 | V5: 41.915 | W5: 154.9 | X5: 55.08 | Y5: 42.54 | Z5: 286.43 | AA5: 0.4 | AB5: 27.9 | AC5: 67.64 | AD5: 643.74 | AE5: 4.73 | AF5: 51.6447 | AG5: 13.1886 | AH5: 570.07 | AI5: 107.43 | AJ5: 117.38 | AK5: 115.47 | AL5: 225.99 | AM5: 44.555 | AN5: 23.3932 | AO5: 51.79 | AP5: 6.34 | AQ5: 128 | AR5: 49.52 | AS5: 122.618 | AT5: 6.32 | AU5: 307.88 | AV5: 238.86 | AW5: 134.83
B6: 45904 | C6: 225.28 | D6: 4 | E6: #N/A N/A | F6: 2.54 | G6: 19.84 | H6: 3.48 | I6: 42.02 | J6: 6.7864 | K6: 47.48 | L6: 49.85 | M6: 259.98 | N6: 33.37 | O6: 29.17 | P6: 14.33 | Q6: 24.54 | R6: 19.82 | S6: 151.49 | T6: 59.48 | U6: 98.21 | V6: 41.865 | W6: 156.14 | X6: 55.71 | Y6: 42.56 | Z6: 289.86 | AA6: 0.4 | AB6: 27.5 | AC6: 68.25 | AD6: 649.12 | AE6: 4.75 | AF6: 51.7739 | AG6: 13.3765 | AH6: 575.23 | AI6: 108.84 | AJ6: 118.81 | AK6: 117.58 | AL6: 235.68 | AM6: 45.76 | AN6: 22.795 | AO6: 50.18 | AP6: 6.36 | AQ6: 129.17 | AR6: 50.54 | AS6: 125.748 | AT6: 6.13 | AU6: 310.38 | AV6: 240.65 | AW6: 137.35
B7: 45905 | C7: 227.72 | D7: 4 | E7: #N/A N/A | F7: 2.59 | G7: 19.83 | H7: 3.47 | I7: 44.04 | J7: 6.8932 | K7: 47.6 | L7: 50.45 | M7: 261.2 | N7: 33.31 | O7: 29.63 | P7: 14.68 | Q7: 24.88 | R7: 19.99 | S7: 150.93 | T7: 59.65 | U7: 101.96 | V7: 41.735 | W7: 153.11 | X7: 56.25 | Y7: 42.56 | Z7: 293.28 | AA7: 0.4 | AB7: 27.1 | AC7: 68.06 | AD7: 647.24 | AE7: 4.74 | AF7: 51.9817 | AG7: 13.7 | AH7: 576.06 | AI7: 105.71 | AJ7: 117.91 | AK7: 117.555 | AL7: 232.33 | AM7: 45.91 | AN7: 23.4718 | AO7: 51.68 | AP7: 6.36 | AQ7: 129.89 | AR7: 52.12 | AS7: 124.382 | AT7: 5.95 | AU7: 315.39 | AV7: 239.68 | AW7: 135.53
B8: 45906 | C8: #N/A N/A | D8: #N/A N/A | E8: #N/A N/A | F8: #N/A N/A | G8: #N/A N/A | H8: #N/A N/A | I8: #N/A N/A | J8: #N/A N/A | K8: #N/A N/A | L8: #N/A N/A | M8: #N/A N/A | N8: #N/A N/A | O8: #N/A N/A | P8: #N/A N/A | Q8: #N/A N/A | R8: #N/A N/A | S8: #N/A N/A | T8: #N/A N/A | U8: #N/A N/A | V8: #N/A N/A | W8: #N/A N/A | X8: #N/A N/A | Y8: #N/A N/A | Z8: #N/A N/A | AA8: #N/A N/A | AB8: #N/A N/A | AC8: #N/A N/A | AD8: #N/A N/A | AE8: #N/A N/A | AF8: #N/A N/A | AG8: #N/A N/A | AH8: #N/A N/A | AI8: #N/A N/A | AJ8: #N/A N/A | AK8: #N/A N/A | AL8: #N/A N/A | AM8: #N/A N/A | AN8: #N/A N/A | AO8: #N/A N/A | AP8: #N/A N/A | AQ8: #N/A N/A | AR8: #N/A N/A | AS8: #N/A N/A | AT8: #N/A N/A | AU8: #N/A N/A | AV8: #N/A N/A | AW8: #N/A N/A
B9: 45907 | C9: #N/A N/A | D9: #N/A N/A | E9: #N/A N/A | F9: #N/A N/A | G9: #N/A N/A | H9: #N/A N/A | I9: #N/A N/A | J9: #N/A N/A | K9: #N/A N/A | L9: #N/A N/A | M9: #N/A N/A | N9: #N/A N/A | O9: #N/A N/A | P9: #N/A N/A | Q9: #N/A N/A | R9: #N/A N/A | S9: #N/A N/A | T9: #N/A N/A | U9: #N/A N/A | V9: #N/A N/A | W9: #N/A N/A | X9: #N/A N/A | Y9: #N/A N/A | Z9: #N/A N/A | AA9: #N/A N/A | AB9: #N/A N/A | AC9: #N/A N/A | AD9: #N/A N/A | AE9: #N/A N/A | AF9: #N/A N/A | AG9: #N/A N/A | AH9: #N/A N/A | AI9: #N/A N/A | AJ9: #N/A N/A | AK9: #N/A N/A | AL9: #N/A N/A | AM9: #N/A N/A | AN9: #N/A N/A | AO9: #N/A N/A | AP9: #N/A N/A | AQ9: #N/A N/A | AR9: #N/A N/A | AS9: #N/A N/A | AT9: #N/A N/A | AU9: #N/A N/A | AV9: #N/A N/A | AW9: #N/A N/A
B10: 45908 | C10: 225 | D10: 4 | E10: #N/A N/A | F10: 2.54 | G10: 20.58 | H10: 3.48 | I10: 43.33 | J10: 6.8447 | K10: 48.07 | L10: 50.91 | M10: 263.5 | N10: 33.55 | O10: 29.58 | P10: 14.57 | Q10: 24.55 | R10: 20.02 | S10: 151.27 | T10: 60.21 | U10: 108.65 | V10: 41.31 | W10: 156.1 | X10: 56.33 | Y10: 42.99 | Z10: 296.52 | AA10: 0.383 | AB10: 27.5 | AC10: 68.05 | AD10: 648.83 | AE10: 4.73 | AF10: 52.0234 | AG10: 13.57 | AH10: 578.87 | AI10: 105.84 | AJ10: 118.84 | AK10: 118.01 | AL10: 235.84 | AM10: 46.565 | AN10: 23.7952 | AO10: 52.16 | AP10: 6.35 | AQ10: 129.78 | AR10: 52.34 | AS10: 124.476 | AT10: 6.17 | AU10: 320.25 | AV10: 248.78 | AW10: 138.69
B11: 45909 | C11: 225.75 | D11: 3.99 | E11: 1.75 | F11: 2.54 | G11: 20.75 | H11: 3.46 | I11: 41.97 | J11: 6.7864 | K11: 48.08 | L11: 51.19 | M11: 263.92 | N11: 33.57 | O11: 29.54 | P11: 14.39 | Q11: 24.71 | R11: 19.6 | S11: 150.25 | T11: 60.21 | U11: 108.47 | V11: 41.595 | W11: 162.36 | X11: 56.02 | Y11: 43.06 | Z11: 297.81 | AA11: 0.375 | AB11: 27.5 | AC11: 68.08 | AD11: 650.33 | AE11: 4.7 | AF11: 52.1809 | AG11: 13.49 | AH11: 580.51 | AI11: 105.54 | AJ11: 117.37 | AK11: 117.845 | AL11: 238.24 | AM11: 46.945 | AN11: 23.8 | AO11: 52.13 | AP11: 6.36 | AQ11: 130.97 | AR11: 53.29 | AS11: 126.325 | AT11: 6.28 | AU11: 347.92 | AV11: 247.86 | AW11: 137.39
B12: 45910 | C12: 225.69 | D12: 3.99 | E12: 1.77 | F12: 2.59 | G12: 20.1 | H12: 3.45 | I12: 41.91 | J12: 6.835 | K12: 48.47 | L12: 51.54 | M12: 264.18 | N12: 33.71 | O12: 29.79 | P12: 14.555 | Q12: 24.57 | R12: 20.04 | S12: 151.36 | T12: 59.95 | U12: 107.6 | V12: 42.31 | W12: 166.74 | X12: 55.62 | Y12: 42.9 | Z12: 300.83 | AA12: 0.392 | AB12: 27.45 | AC12: 68.11 | AD12: 652.21 | AE12: 4.65 | AF12: 51.6893 | AG12: 13.5454 | AH12: 580.7 | AI12: 105.67 | AJ12: 115.79 | AK12: 116.435 | AL12: 230.33 | AM12: 46.995 | AN12: 23.86 | AO12: 52.24 | AP12: 6.35 | AQ12: 128.01 | AR12: 53.59 | AS12: 124.771 | AT12: 5.72 | AU12: 346.78 | AV12: 244.04 | AW12: 139.29
B13: 45911 | C13: 228.81 | D13: 4.01 | E13: #N/A N/A | F13: 2.57 | G13: 20.58 | H13: 3.45 | I13: 41.86 | J13: 6.8738 | K13: 48.98 | L13: 52.29 | M13: 266.59 | N13: 34.1 | O13: 30.05 | P13: 14.69 | Q13: 24.86 | R13: 20.18 | S13: 152.8 | T13: 60.63 | U13: 111.82 | V13: 42.535 | W13: 164.36 | X13: 56.12 | Y13: 43.53 | Z13: 303.93 | AA13: 0.397 | AB13: 27.5 | AC13: 69.05 | AD13: 657.63 | AE13: 4.65 | AF13: 52.3269 | AG13: 13.73 | AH13: 584.08 | AI13: 106.99 | AJ13: 117.08 | AK13: 118.7 | AL13: 229.95 | AM13: 47.785 | AN13: 24.9417 | AO13: 54.65 | AP13: 6.37 | AQ13: 129.47 | AR13: 52.35 | AS13: 120.35 | AT13: 6.07 | AU13: 353.61 | AV13: 246.54 | AW13: 145.01
B14: 45912 | C14: 229.55 | D14: 4.01 | E14: 1.76 | F14: 2.57 | G14: 20.87 | H14: 3.37 | I14: 41.78 | J14: 6.767 | K14: 49 | L14: 52.26 | M14: 266.06 | N14: 34.1 | O14: 30.03 | P14: 14.63 | Q14: 23.87 | R14: 20.07 | S14: 151.58 | T14: 60.59 | U14: 114.78 | V14: 42.75 | W14: 171.43 | X14: 55.65 | Y14: 43.49 | Z14: 304.32 | AA14: 0.42 | AB14: 27.5 | AC14: 68.68 | AD14: 657.41 | AE14: 4.71 | AF14: 51.7648 | AG14: 13.78 | AH14: 586.66 | AI14: 106.9 | AJ14: 115.96 | AK14: 119.315 | AL14: 228.15 | AM14: 48.38 | AN14: 24.87 | AO14: 54.69 | AP14: 6.33 | AQ14: 127.99 | AR14: 51.87 | AS14: 118.844 | AT14: 6.22 | AU14: 352.51 | AV14: 246.26 | AW14: 143.34
B15: 45913 | C15: #N/A N/A | D15: #N/A N/A | E15: #N/A N/A | F15: #N/A N/A | G15: #N/A N/A | H15: #N/A N/A | I15: #N/A N/A | J15: #N/A N/A | K15: #N/A N/A | L15: #N/A N/A | M15: #N/A N/A | N15: #N/A N/A | O15: #N/A N/A | P15: #N/A N/A | Q15: #N/A N/A | R15: #N/A N/A | S15: #N/A N/A | T15: #N/A N/A | U15: #N/A N/A | V15: #N/A N/A | W15: #N/A N/A | X15: #N/A N/A | Y15: #N/A N/A | Z15: #N/A N/A | AA15: #N/A N/A | AB15: #N/A N/A | AC15: #N/A N/A | AD15: #N/A N/A | AE15: #N/A N/A | AF15: #N/A N/A | AG15: #N/A N/A | AH15: #N/A N/A | AI15: #N/A N/A | AJ15: #N/A N/A | AK15: #N/A N/A | AL15: #N/A N/A | AM15: #N/A N/A | AN15: #N/A N/A | AO15: #N/A N/A | AP15: #N/A N/A | AQ15: #N/A N/A | AR15: #N/A N/A | AS15: #N/A N/A | AT15: #N/A N/A | AU15: #N/A N/A | AV15: #N/A N/A | AW15: #N/A N/A
B16: 45914 | C16: #N/A N/A | D16: #N/A N/A | E16: #N/A N/A | F16: #N/A N/A | G16: #N/A N/A | H16: #N/A N/A | I16: #N/A N/A | J16: #N/A N/A | K16: #N/A N/A | L16: #N/A N/A | M16: #N/A N/A | N16: #N/A N/A | O16: #N/A N/A | P16: #N/A N/A | Q16: #N/A N/A | R16: #N/A N/A | S16: #N/A N/A | T16: #N/A N/A | U16: #N/A N/A | V16: #N/A N/A | W16: #N/A N/A | X16: #N/A N/A | Y16: #N/A N/A | Z16: #N/A N/A | AA16: #N/A N/A | AB16: #N/A N/A | AC16: #N/A N/A | AD16: #N/A N/A | AE16: #N/A N/A | AF16: #N/A N/A | AG16: #N/A N/A | AH16: #N/A N/A | AI16: #N/A N/A | AJ16: #N/A N/A | AK16: #N/A N/A | AL16: #N/A N/A | AM16: #N/A N/A | AN16: #N/A N/A | AO16: #N/A N/A | AP16: #N/A N/A | AQ16: #N/A N/A | AR16: #N/A N/A | AS16: #N/A N/A | AT16: #N/A N/A | AU16: #N/A N/A | AV16: #N/A N/A | AW16: #N/A N/A
B17: 45915 | C17: 225.69 | D17: 4.01 | E17: 1.76 | F17: 2.55 | G17: 21.33 | H17: 3.34 | I17: 42.35 | J17: 6.932 | K17: 49.23 | L17: 52.64 | M17: 265.64 | N17: 34.43 | O17: 30.51 | P17: 14.81 | Q17: 23.97 | R17: 20.65 | S17: 152.28 | T17: 61.17 | U17: 114.82 | V17: 42.85 | W17: 171.21 | X17: 55.56 | Y17: 43.89 | Z17: 307.17 | AA17: 0.411 | AB17: 27.39 | AC17: 68.72 | AD17: 660.91 | AE17: 4.73 | AF17: 51.349 | AG17: 13.98 | AH17: 591.68 | AI17: 105.45 | AJ17: 115.62 | AK17: 120.35 | AL17: 231.43 | AM17: 49.615 | AN17: 25.04 | AO17: 55 | AP17: 6.37 | AQ17: 125.47 | AR17: 51.79 | AS17: 120.226 | AT17: 6.49 | AU17: 347.89 | AV17: 247.25 | AW17: 144.65
B18: 45916 | C18: 227.7 | D18: 4.01 | E18: #N/A N/A | F18: 2.53 | G18: 21.45 | H18: 3.36 | I18: 42.67 | J18: 6.932 | K18: 48.95 | L18: 53.03 | M18: 270.79 | N18: 34.04 | O18: 30.69 | P18: 14.89 | Q18: 23.9 | R18: 20.11 | S18: 151.83 | T18: 61.01 | U18: 123.79 | V18: 42.07 | W18: 170.26 | X18: 55.48 | Y18: 43.82 | Z18: 307.21 | AA18: 0.416 | AB18: 27.39 | AC18: 68.53 | AD18: 660 | AE18: 4.75 | AF18: 51.3441 | AG18: 14.14 | AH18: 591.18 | AI18: 102.15 | AJ18: 115.23 | AK18: 121.09 | AL18: 234.05 | AM18: 49.48 | AN18: 25.36 | AO18: 55.96 | AP18: 6.36 | AQ18: 125.04 | AR18: 51.72 | AS18: 120.051 | AT18: 7.02 | AU18: 339.78 | AV18: 247.73 | AW18: 144.38
B19: 45917 | C19: 225.78 | D19: 4.03 | E19: 1.76 | F19: 2.55 | G19: 21.6 | H19: 3.36 | I19: 42.86 | J19: 7.0583 | K19: 48.75 | L19: 53.26 | M19: 278.29 | N19: 33.97 | O19: 30.94 | P19: 15.06 | Q19: 24.05 | R19: 19.82 | S19: 151.14 | T19: 60.69 | U19: 137.83 | V19: 42.175 | W19: 168.33 | X19: 55.29 | Y19: 43.53 | Z19: 305.25 | AA19: 0.412 | AB19: 27.3 | AC19: 68.74 | AD19: 659.18 | AE19: 4.74 | AF19: 51.3708 | AG19: 14.27 | AH19: 590 | AI19: 103.01 | AJ19: 116.1 | AK19: 120.785 | AL19: 231.62 | AM19: 49.165 | AN19: 26.055 | AO19: 57.67 | AP19: 6.35 | AQ19: 125.59 | AR19: 52.03 | AS19: 122.85 | AT19: 7.45 | AU19: 341.61 | AV19: 250.52 | AW19: 144.4
B20: 45918 | C20: 226.5 | D20: 4 | E20: #N/A N/A | F20: 2.55 | G20: 21.29 | H20: 3.34 | I20: 42.81 | J20: 7.0194 | K20: 48.66 | L20: 53.13 | M20: 261.91 | N20: 34.01 | O20: 30.82 | P20: 15.04 | Q20: 24.15 | R20: 20.02 | S20: 152.75 | T20: 61.18 | U20: 135.25 | V20: 42.205 | W20: 176.97 | X20: 55.21 | Y20: 43.84 | Z20: 316.97 | AA20: 0.401 | AB20: 26.9 | AC20: 69 | AD20: 662.26 | AE20: 4.72 | AF20: 51.5728 | AG20: 14.2 | AH20: 595.32 | AI20: 103.87 | AJ20: 114.86 | AK20: 120.24 | AL20: 231.23 | AM20: 50.49 | AN20: 25.8 | AO20: 57.39 | AP20: 6.345 | AQ20: 125.51 | AR20: 51.56 | AS20: 120.778 | AT20: 7.37 | AU20: 334.82 | AV20: 249.74 | AW20: 149.34
B21: 45919 | C21: 231.75 | D21: 3.99 | E21: #N/A N/A | F21: 2.5 | G21: 21.66 | H21: 3.37 | I21: 43.17 | J21: 7.1165 | K21: 48.83 | L21: 53.01 | M21: 262.61 | N21: 33.97 | O21: 30.93 | P21: 15.17 | Q21: 24.03 | R21: 20.91 | S21: 153.12 | T21: 61.05 | U21: 135.35 | V21: 42.475 | W21: 182.39 | X21: 55.26 | Y21: 43.68 | Z21: 315.71 | AA21: 0.418 | AB21: 26.85 | AC21: 68.81 | AD21: 663.7 | AE21: 4.73 | AF21: 51.4212 | AG21: 14.19 | AH21: 599.35 | AI21: 103.59 | AJ21: 113.76 | AK21: 120.695 | AL21: 231.48 | AM21: 51.49 | AN21: 25.6 | AO21: 56.86 | AP21: 6.45 | AQ21: 124.62 | AR21: 51.88 | AS21: 122.697 | AT21: 7.37 | AU21: 336.69 | AV21: 250.85 | AW21: 148.92
B22: 45920 | C22: #N/A N/A | D22: #N/A N/A | E22: #N/A N/A | F22: #N/A N/A | G22: #N/A N/A | H22: #N/A N/A | I22: #N/A N/A | J22: #N/A N/A | K22: #N/A N/A | L22: #N/A N/A | M22: #N/A N/A | N22: #N/A N/A | O22: #N/A N/A | P22: #N/A N/A | Q22: #N/A N/A | R22: #N/A N/A | S22: #N/A N/A | T22: #N/A N/A | U22: #N/A N/A | V22: #N/A N/A | W22: #N/A N/A | X22: #N/A N/A | Y22: #N/A N/A | Z22: #N/A N/A | AA22: #N/A N/A | AB22: #N/A N/A | AC22: #N/A N/A | AD22: #N/A N/A | AE22: #N/A N/A | AF22: #N/A N/A | AG22: #N/A N/A | AH22: #N/A N/A | AI22: #N/A N/A | AJ22: #N/A N/A | AK22: #N/A N/A | AL22: #N/A N/A | AM22: #N/A N/A | AN22: #N/A N/A | AO22: #N/A N/A | AP22: #N/A N/A | AQ22: #N/A N/A | AR22: #N/A N/A | AS22: #N/A N/A | AT22: #N/A N/A | AU22: #N/A N/A | AV22: #N/A N/A | AW22: #N/A N/A
B23: 45921 | C23: #N/A N/A | D23: #N/A N/A | E23: #N/A N/A | F23: #N/A N/A | G23: #N/A N/A | H23: #N/A N/A | I23: #N/A N/A | J23: #N/A N/A | K23: #N/A N/A | L23: #N/A N/A | M23: #N/A N/A | N23: #N/A N/A | O23: #N/A N/A | P23: #N/A N/A | Q23: #N/A N/A | R23: #N/A N/A | S23: #N/A N/A | T23: #N/A N/A | U23: #N/A N/A | V23: #N/A N/A | W23: #N/A N/A | X23: #N/A N/A | Y23: #N/A N/A | Z23: #N/A N/A | AA23: #N/A N/A | AB23: #N/A N/A | AC23: #N/A N/A | AD23: #N/A N/A | AE23: #N/A N/A | AF23: #N/A N/A | AG23: #N/A N/A | AH23: #N/A N/A | AI23: #N/A N/A | AJ23: #N/A N/A | AK23: #N/A N/A | AL23: #N/A N/A | AM23: #N/A N/A | AN23: #N/A N/A | AO23: #N/A N/A | AP23: #N/A N/A | AQ23: #N/A N/A | AR23: #N/A N/A | AS23: #N/A N/A | AT23: #N/A N/A | AU23: #N/A N/A | AV23: #N/A N/A | AW23: #N/A N/A
B24: 45922 | C24: 230.12 | D24: 4 | E24: #N/A N/A | F24: 2.5 | G24: 21.36 | H24: 3.37 | I24: 43.89 | J24: 7.0291 | K24: 48.43 | L24: 53.27 | M24: 266.77 | N24: 34.04 | O24: 30.79 | P24: 15.36 | Q24: 24.04 | R24: 21.53 | S24: 153 | T24: 61.18 | U24: 136.63 | V24: 42.6 | W24: 179.33 | X24: 55.57 | Y24: 43.78 | Z24: 322.17 | AA24: 0.44 | AB24: 26.8 | AC24: 68.83 | AD24: 666.84 | AE24: 4.73 | AF24: 51.6088 | AG24: 13.96 | AH24: 602.2 | AI24: 102.85 | AJ24: 112.56 | AK24: 120.09 | AL24: 227.63 | AM24: 52.36 | AN24: 25.97 | AO24: 57.84 | AP24: 6.39 | AQ24: 124.07 | AR24: 52.51 | AS24: 122.737 | AT24: 6.91 | AU24: 341.3 | AV24: 251.64 | AW24: 146.95
B25: 45923 | C25: 233.7 | D25: 4 | E25: 1.77 | F25: 2.49 | G25: 21.19 | H25: 3.36 | I25: 42.37 | J25: 7.1942 | K25: 48.55 | L25: 53.3 | M25: 265.55 | N25: 34.01 | O25: 31.32 | P25: 15.19 | Q25: 24.13 | R25: 22.05 | S25: 153.04 | T25: 61.33 | U25: 125.57 | V25: 42.82 | W25: 182.55 | X25: 55.24 | Y25: 43.89 | Z25: 321.7 | AA25: 0.455 | AB25: 26.71 | AC25: 68.62 | AD25: 663.21 | AE25: 4.73 | AF25: 51.4841 | AG25: 14.18 | AH25: 598.2 | AI25: 103.13 | AJ25: 112.25 | AK25: 118.96 | AL25: 220.71 | AM25: 51.305 | AN25: 25.5 | AO25: 56.28 | AP25: 6.46 | AQ25: 123.82 | AR25: 52.58 | AS25: 121.847 | AT25: 6.93 | AU25: 347.69 | AV25: 251.28 | AW25: 147.25
B26: 45924 | C26: 233.75 | D26: 4.01 | E26: #N/A N/A | F26: 2.5 | G26: 21.27 | H26: 3.37 | I26: 43.35 | J26: 7.0777 | K26: 48.57 | L26: 53.12 | M26: 266.11 | N26: 33.83 | O26: 31.05 | P26: 15.14 | Q26: 24.09 | R26: 22.86 | S26: 152.25 | T26: 61.02 | U26: 132.92 | V26: 43.125 | W26: 179.56 | X26: 54.51 | Y26: 43.41 | Z26: 321.11 | AA26: 0.45 | AB26: 26.5 | AC26: 68.42 | AD26: 661.1 | AE26: 4.72 | AF26: 51.2638 | AG26: 14.04 | AH26: 596.1 | AI26: 103.32 | AJ26: 113.43 | AK26: 119.8 | AL26: 220.21 | AM26: 50.705 | AN26: 26.08 | AO26: 57.63 | AP26: 6.63 | AQ26: 123.93 | AR26: 52.46 | AS26: 120.395 | AT26: 7.12 | AU26: 351.81 | AV26: 244.12 | AW26: 137.94
B27: 45925 | C27: 236.42 | D27: 4.02 | E27: 1.75 | F27: 2.5 | G27: 22.25 | H27: 3.35 | I27: 43.71 | J27: 6.9903 | K27: 48.25 | L27: 52.81 | M27: 262.74 | N27: 33.56 | O27: 30.58 | P27: 15.16 | Q27: 23.6 | R27: 22.92 | S27: 151.22 | T27: 60.54 | U27: 135.4 | V27: 42.71 | W27: 179.12 | X27: 53.86 | Y27: 43.05 | Z27: 321.06 | AA27: 0.438 | AB27: 26.44 | AC27: 68.07 | AD27: 658.05 | AE27: 4.7 | AF27: 50.3972 | AG27: 13.745 | AH27: 593.53 | AI27: 102.62 | AJ27: 112.99 | AK27: 118.11 | AL27: 218.15 | AM27: 50.025 | AN27: 26.35 | AO27: 58.24 | AP27: 6.71 | AQ27: 121.72 | AR27: 52.44 | AS27: 120.824 | AT27: 7.47 | AU27: 345.56 | AV27: 245.11 | AW27: 135.66
B28: 45926 | C28: 237.82 | D28: 4.01 | E28: 1.77 | F28: 2.48 | G28: 22.79 | H28: 3.32 | I28: 43.42 | J28: 7.0291 | K28: 49.04 | L28: 52.71 | M28: 263.66 | N28: 34.14 | O28: 30.73 | P28: 15.21 | Q28: 23.76 | R28: 23.24 | S28: 152.58 | T28: 61.28 | U28: 131.34 | V28: 43.405 | W28: 177.57 | X28: 54.26 | Y28: 43.59 | Z28: 321.82 | AA28: 0.457 | AB28: 26.27 | AC28: 68.56 | AD28: 661.82 | AE28: 4.73 | AF28: 50.9384 | AG28: 13.8654 | AH28: 595.97 | AI28: 104.41 | AJ28: 113.47 | AK28: 119.855 | AL28: 219.78 | AM28: 50.625 | AN28: 25.7407 | AO28: 57.1 | AP28: 6.66 | AQ28: 122.23 | AR28: 51.93 | AS28: 121.061 | AT28: 7.04 | AU28: 344.08 | AV28: 256.12 | AW28: 134.01
B29: 45927 | C29: #N/A N/A | D29: #N/A N/A | E29: #N/A N/A | F29: #N/A N/A | G29: #N/A N/A | H29: #N/A N/A | I29: #N/A N/A | J29: #N/A N/A | K29: #N/A N/A | L29: #N/A N/A | M29: #N/A N/A | N29: #N/A N/A | O29: #N/A N/A | P29: #N/A N/A | Q29: #N/A N/A | R29: #N/A N/A | S29: #N/A N/A | T29: #N/A N/A | U29: #N/A N/A | V29: #N/A N/A | W29: #N/A N/A | X29: #N/A N/A | Y29: #N/A N/A | Z29: #N/A N/A | AA29: #N/A N/A | AB29: #N/A N/A | AC29: #N/A N/A | AD29: #N/A N/A | AE29: #N/A N/A | AF29: #N/A N/A | AG29: #N/A N/A | AH29: #N/A N/A | AI29: #N/A N/A | AJ29: #N/A N/A | AK29: #N/A N/A | AL29: #N/A N/A | AM29: #N/A N/A | AN29: #N/A N/A | AO29: #N/A N/A | AP29: #N/A N/A | AQ29: #N/A N/A | AR29: #N/A N/A | AS29: #N/A N/A | AT29: #N/A N/A | AU29: #N/A N/A | AV29: #N/A N/A | AW29: #N/A N/A
B30: 45928 | C30: #N/A N/A | D30: #N/A N/A | E30: #N/A N/A | F30: #N/A N/A | G30: #N/A N/A | H30: #N/A N/A | I30: #N/A N/A | J30: #N/A N/A | K30: #N/A N/A | L30: #N/A N/A | M30: #N/A N/A | N30: #N/A N/A | O30: #N/A N/A | P30: #N/A N/A | Q30: #N/A N/A | R30: #N/A N/A | S30: #N/A N/A | T30: #N/A N/A | U30: #N/A N/A | V30: #N/A N/A | W30: #N/A N/A | X30: #N/A N/A | Y30: #N/A N/A | Z30: #N/A N/A | AA30: #N/A N/A | AB30: #N/A N/A | AC30: #N/A N/A | AD30: #N/A N/A | AE30: #N/A N/A | AF30: #N/A N/A | AG30: #N/A N/A | AH30: #N/A N/A | AI30: #N/A N/A | AJ30: #N/A N/A | AK30: #N/A N/A | AL30: #N/A N/A | AM30: #N/A N/A | AN30: #N/A N/A | AO30: #N/A N/A | AP30: #N/A N/A | AQ30: #N/A N/A | AR30: #N/A N/A | AS30: #N/A N/A | AT30: #N/A N/A | AU30: #N/A N/A | AV30: #N/A N/A | AW30: #N/A N/A
B31: 45929 | C31: 236.58 | D31: 4.02 | E31: 1.77 | F31: 2.5 | G31: 23.19 | H31: 3.35 | I31: 43.82 | J31: 7.1165 | K31: 48.92 | L31: 53.19 | M31: 267.47 | N31: 34.16 | O31: 30.99 | P31: 15.41 | Q31: 23.85 | R31: 24.33 | S31: 153.05 | T31: 61.52 | U31: 134.86 | V31: 43.53 | W31: 178.86 | X31: 54.57 | Y31: 43.78 | Z31: 322.66 | AA31: 0.472 | AB31: 26 | AC31: 68.76 | AD31: 663.68 | AE31: 4.72 | AF31: 51.2522 | AG31: 13.985 | AH31: 598.73 | AI31: 103.83 | AJ31: 114.78 | AK31: 120.38 | AL31: 222.17 | AM31: 51.3 | AN31: 26.34 | AO31: 58.2 | AP31: 6.7 | AQ31: 122.66 | AR31: 51.56 | AS31: 120.641 | AT31: 7.21 | AU31: 345.18 | AV31: 259.96 | AW31: 134.48
B32: 45930 | C32: 235.81 | D32: 4.01 | E32: 1.77 | F32: 2.49 | G32: 23.42 | H32: 3.31 | I32: 43.63 | J32: 7.1262 | K32: 49.5 | L32: 53.4 | M32: 266.28 | N32: 34.34 | O32: 31 | P32: 15.48 | Q32: 25.48 | R32: 24.33 | S32: 154.23 | T32: 61.94 | U32: 131.77 | V32: 43.605 | W32: 182.42 | X32: 55.24 | Y32: 43.93 | Z32: 326.36 | AA32: 0.48 | AB32: 26 | AC32: 68.96 | AD32: 666.18 | AE32: 4.73 | AF32: 52.4147 | AG32: 13.9 | AH32: 600.37 | AI32: 103.74 | AJ32: 114.5 | AK32: 119.82 | AL32: 219.57 | AM32: 51.7 | AN32: 26.5512 | AO32: 59.01 | AP32: 6.72 | AQ32: 124.34 | AR32: 51.94 | AS32: 119.892 | AT32: 7.62 | AU32: 345.3 | AV32: 258.36 | AW32: 129.95
B33: 45931 | C33: 239.55 | D33: 4.03 | E33: 1.8 | F33: 2.49 | G33: 23.7 | H33: 3.33 | I33: 45.08 | J33: 6.9806 | K33: 49.64 | L33: 53.82 | M33: 262.2 | N33: 34.44 | O33: 30.58 | P33: 15.88 | Q33: 27.21 | R33: 24.65 | S33: 153.8 | T33: 62.63 | U33: 137.44 | V33: 44.025 | W33: 184.95 | X33: 55.94 | Y33: 44.49 | Z33: 333.69 | AA33: 0.5 | AB33: 25.6 | AC33: 69.14 | AD33: 668.45 | AE33: 4.72 | AF33: 53.985 | AG33: 13.7849 | AH33: 603.25 | AI33: 102.99 | AJ33: 112.95 | AK33: 120.57 | AL33: 220.63 | AM33: 52.43 | AN33: 26.7565 | AO33: 59.71 | AP33: 6.75 | AQ33: 123.23 | AR33: 52.02 | AS33: 117.09 | AT33: 7.65 | AU33: 348.3 | AV33: 255.4 | AW33: 127.47
B34: 45932 | C34: 242.32 | D34: 4 | E34: 1.78 | F34: 2.49 | G34: 23.81 | H34: 3.33 | I34: 46.18 | J34: 6.9126 | K34: 49.36 | L34: 54.07 | M34: 259.09 | N34: 34.31 | O34: 30.24 | P34: 15.89 | Q34: 27.08 | R34: 24.93 | S34: 154.2 | T34: 63 | U34: 140.23 | V34: 43.945 | W34: 187.05 | X34: 56.25 | Y34: 44.77 | Z34: 338.24 | AA34: 0.498 | AB34: 25.5 | AC34: 69.09 | AD34: 669.22 | AE34: 4.72 | AF34: 53.8388 | AG34: 13.625 | AH34: 605.73 | AI34: 101.94 | AJ34: 112.14 | AK34: 119.7 | AL34: 222.41 | AM34: 53.07 | AN34: 27.27 | AO34: 60.41 | AP34: 6.75 | AQ34: 122.62 | AR34: 51.36 | AS34: 116.253 | AT34: 7.89 | AU34: 353.72 | AV34: 256.94 | AW34: 124.63
B35: 45933 | C35: 244.61 | D35: 3.99 | E35: 1.8 | F35: 2.48 | G35: 23.07 | H35: 3.34 | I35: 45.98 | J35: 6.9612 | K35: 49.65 | L35: 54.23 | M35: 266.19 | N35: 34.54 | O35: 30.33 | P35: 15.98 | Q35: 27.37 | R35: 24.49 | S35: 154.41 | T35: 63.11 | U35: 142 | V35: 44.455 | W35: 173.07 | X35: 56.66 | Y35: 44.91 | Z35: 336.68 | AA35: 0.51 | AB35: 25.5 | AC35: 69.46 | AD35: 669.21 | AE35: 4.72 | AF35: 54.4453 | AG35: 13.655 | AH35: 603.18 | AI35: 104.02 | AJ35: 112.47 | AK35: 118.93 | AL35: 219.51 | AM35: 52.35 | AN35: 27.0613 | AO35: 60.24 | AP35: 6.77 | AQ35: 122.58 | AR35: 52.17 | AS35: 115.332 | AT35: 7.7 | AU35: 360.2 | AV35: 257.68 | AW35: 127.65
B36: 45934 | C36: #N/A N/A | D36: #N/A N/A | E36: #N/A N/A | F36: #N/A N/A | G36: #N/A N/A | H36: #N/A N/A | I36: #N/A N/A | J36: #N/A N/A | K36: #N/A N/A | L36: #N/A N/A | M36: #N/A N/A | N36: #N/A N/A | O36: #N/A N/A | P36: #N/A N/A | Q36: #N/A N/A | R36: #N/A N/A | S36: #N/A N/A | T36: #N/A N/A | U36: #N/A N/A | V36: #N/A N/A | W36: #N/A N/A | X36: #N/A N/A | Y36: #N/A N/A | Z36: #N/A N/A | AA36: #N/A N/A | AB36: #N/A N/A | AC36: #N/A N/A | AD36: #N/A N/A | AE36: #N/A N/A | AF36: #N/A N/A | AG36: #N/A N/A | AH36: #N/A N/A | AI36: #N/A N/A | AJ36: #N/A N/A | AK36: #N/A N/A | AL36: #N/A N/A | AM36: #N/A N/A | AN36: #N/A N/A | AO36: #N/A N/A | AP36: #N/A N/A | AQ36: #N/A N/A | AR36: #N/A N/A | AS36: #N/A N/A | AT36: #N/A N/A | AU36: #N/A N/A | AV36: #N/A N/A | AW36: #N/A N/A
B37: 45935 | C37: #N/A N/A | D37: #N/A N/A | E37: #N/A N/A | F37: #N/A N/A | G37: #N/A N/A | H37: #N/A N/A | I37: #N/A N/A | J37: #N/A N/A | K37: #N/A N/A | L37: #N/A N/A | M37: #N/A N/A | N37: #N/A N/A | O37: #N/A N/A | P37: #N/A N/A | Q37: #N/A N/A | R37: #N/A N/A | S37: #N/A N/A | T37: #N/A N/A | U37: #N/A N/A | V37: #N/A N/A | W37: #N/A N/A | X37: #N/A N/A | Y37: #N/A N/A | Z37: #N/A N/A | AA37: #N/A N/A | AB37: #N/A N/A | AC37: #N/A N/A | AD37: #N/A N/A | AE37: #N/A N/A | AF37: #N/A N/A | AG37: #N/A N/A | AH37: #N/A N/A | AI37: #N/A N/A | AJ37: #N/A N/A | AK37: #N/A N/A | AL37: #N/A N/A | AM37: #N/A N/A | AN37: #N/A N/A | AO37: #N/A N/A | AP37: #N/A N/A | AQ37: #N/A N/A | AR37: #N/A N/A | AS37: #N/A N/A | AT37: #N/A N/A | AU37: #N/A N/A | AV37: #N/A N/A | AW37: #N/A N/A
B38: 45936 | C38: 247.03 | D38: 4.15 | E38: 1.78 | F38: 2.47 | G38: 23.63 | H38: 3.33 | I38: 46.24 | J38: 6.9223 | K38: 49.22 | L38: 54.48 | M38: 264.69 | N38: 34.3 | O38: 30.31 | P38: 16.08 | Q38: 26.43 | R38: 24.79 | S38: 155.13 | T38: 62.74 | U38: 144.91 | V38: 44.885 | W38: 179.53 | X38: 56.72 | Y38: 44.19 | Z38: 343.38 | AA38: 0.52 | AB38: 25.99 | AC38: 69.43 | AD38: 671.61 | AE38: 4.72 | AF38: 54.2478 | AG38: 13.59 | AH38: 607.71 | AI38: 103.22 | AJ38: 112.75 | AK38: 119.95 | AL38: 220.9 | AM38: 53.52 | AN38: 27.05 | AO38: 60.47 | AP38: 6.75 | AQ38: 120.54 | AR38: 52.16 | AS38: 116.331 | AT38: 7.59 | AU38: 358.77 | AV38: 256.98 | AW38: 126.87
B39: 45937 | C39: 242.33 | D39: 4.35 | E39: 1.78 | F39: 2.42 | G39: 23.67 | H39: 3.33 | I39: 45.68 | J39: 6.7379 | K39: 48.92 | L39: 54.06 | M39: 262.62 | N39: 33.99 | O39: 29.68 | P39: 15.89 | Q39: 26.27 | R39: 24.44 | S39: 154.25 | T39: 62.12 | U39: 138.94 | V39: 45.09 | W39: 182.17 | X39: 56.55 | Y39: 43.79 | Z39: 337.05 | AA39: 0.494 | AB39: 26.5 | AC39: 69.08 | AD39: 669.12 | AE39: 4.72 | AF39: 54.205 | AG39: 13.245 | AH39: 604.51 | AI39: 103.71 | AJ39: 112.53 | AK39: 117.85 | AL39: 221.78 | AM39: 52.655 | AN39: 26.68 | AO39: 59.65 | AP39: 6.61 | AQ39: 122.33 | AR39: 51.99 | AS39: 119.106 | AT39: 7.5 | AU39: 363.66 | AV39: 260.5 | AW39: 124.72
B40: 45938 | C40: 239.93 | D40: #N/A N/A | E40: #N/A N/A | F40: #N/A N/A | G40: 24.19 | H40: #N/A N/A | I40: 46.14 | J40: 6.7573 | K40: 49.33 | L40: 54.49 | M40: 264.5 | N40: 34.29 | O40: 29.87 | P40: 16.01 | Q40: 25.68 | R40: 26.26 | S40: 155.59 | T40: 62.52 | U40: 137.9 | V40: 45.4 | W40: 183.56 | X40: 56.83 | Y40: 44.3 | Z40: 346.07 | AA40: #N/A N/A | AB40: #N/A N/A | AC40: 69.2 | AD40: 673.11 | AE40: #N/A N/A | AF40: 54.2993 | AG40: 13.3239 | AH40: 611.44 | AI40: 102.89 | AJ40: 111.89 | AK40: 118.2 | AL40: 225.22 | AM40: 54.44 | AN40: 26.7774 | AO40: 59.67 | AP40: 6.47 | AQ40: 119.63 | AR40: 52.78 | AS40: 121.425 | AT40: 7.85 | AU40: 369.92 | AV40: 258.07 | AW40: 124.73
B41: 45939 | C41: 237 | D41: 4.5 | E41: 1.78 | F41: 2.47 | G41: 22.91 | H41: 3.31 | I41: 47.54 | J41: 6.7282 | K41: 48.67 | L41: 53.93 | M41: 261.24 | N41: 33.74 | O41: 29.67 | P41: 16.14 | Q41: 25.24 | R41: 24.93 | S41: 153.29 | T41: 61.92 | U41: 132.4 | V41: 45.285 | W41: 185.47 | X41: 56.36 | Y41: 43.89 | Z41: 345.21 | AA41: 0.497 | AB41: 27 | AC41: 68.69 | AD41: 671.16 | AE41: 4.7 | AF41: 54.2953 | AG41: 13.155 | AH41: 610.7 | AI41: 102.56 | AJ41: 110.99 | AK41: 117.61 | AL41: 227.74 | AM41: 54.225 | AN41: 26.58 | AO41: 58.86 | AP41: 6.58 | AQ41: 119.55 | AR41: 54.46 | AS41: 123.107 | AT41: 7.46 | AU41: 367.69 | AV41: 256.69 | AW41: 124.06
...

Sheet BP
C2: FDX | D2: MINSURI1 | E2: SIDERC1 | F2: ORYGENC1 | G2: XPEV | H2: FERREYC1 | I2: TAN | J2: ITUB | K2: EWP | L2: EEM | M2: BAP | N2: EUFN | O2: EWZ | P2: ICLN | Q2: PFE | R2: BVN | S2: XLI | T2: EZU | U2: BIDU | V2: XLU | W2: PLTR | X2: EWL | Y2: EWQ | Z2: SMH | AA2: VOLCABC1 | AB2: INRETC1 | AC2: JAVA | AD2: SPY | AE2: CPACASC1 | AF2: JDOC | AG2: EWZS | AH2: QQQ | AI2: PRU | AJ2: DIS | AK2: XLY | AL2: AMZN | AM2: TQQQ | AN2: TCHI | AO2: CQQQ | AP2: AUNA | AQ2: KMB | AR2: CIB | AS2: NFLX | AT2: NIO | AU2: UNH | AV2: TTWO | AW2: KKR
B3: 45901 | C3: {=_xll.BDH(C$2 & " US Equity","PX_LAST",$B3,$B3)} -> #N/A N/A | D3: {=_xll.BDH(D$2 & " PE Equity","PX_LAST",$B3,$B3)} -> 3.98 | E3: {=_xll.BDH(E$2 & " PE Equity","PX_LAST",$B3,$B3)} -> 1.76 | F3: {=_xll.BDH(F$2 & " PE Equity","PX_LAST",$B3,$B3)} -> 2.55 | G3: {=_xll.BDH(G$2 & " US Equity","PX_LAST",$B3,$B3)} -> #N/A N/A | H3: {=_xll.BDH(H$2 & " PE Equity","PX_LAST",$B3,$B3)} -> 3.49 | I3: {=_xll.BDH(I$2 & " US Equity","PX_LAST",$B3,$B3)} -> #N/A N/A | J3: {=_xll.BDH(J$2 & " US Equity","PX_LAST",$B3,$B3)} -> #N/A N/A | K3: {=_xll.BDH(K$2 & " US Equity","PX_LAST",$B3,$B3)} -> #N/A N/A | L3: {=_xll.BDH(L$2 & " US Equity","PX_LAST",$B3,$B3)} -> #N/A N/A | M3: {=_xll.BDH(M$2 & " US Equity","PX_LAST",$B3,$B3)} -> #N/A N/A | N3: {=_xll.BDH(N$2 & " US Equity","PX_LAST",$B3,$B3)} -> #N/A N/A | O3: {=_xll.BDH(O$2 & " US Equity","PX_LAST",$B3,$B3)} -> #N/A N/A | P3: {=_xll.BDH(P$2 & " US Equity","PX_LAST",$B3,$B3)} -> #N/A N/A | ... Z3: {=_xll.BDH(Z$2 & " US Equity","PX_LAST",$B3,$B3)} -> #N/A N/A | AA3: {=_xll.BDH(AA$2 & " PE Equity","PX_LAST",$B3,$B3)} -> 0.376 | AB3: {=_xll.BDH(AB$2 & " PE Equity","PX_LAST",$B3,$B3)} -> 27.5 | AC3: {=_xll.BDH(AC$2 & " US Equity","PX_LAST",$B3,$B3)} -> #N/A N/A | AD3: {=_xll.BDH(AD$2 & " US Equity","PX_LAST",$B3,$B3)} -> #N/A N/A | AE3: {=_xll.BDH(AE$2 & " PE Equity","PX_LAST",$B3,$B3)} -> #N/A Connection | AF3: {=_xll.BDH(AF$2 & " US Equity","PX_LAST",$B3,$B3)} -> #N/A N/A | AG3: {=_xll.BDH(AG$2 & " US Equity","PX_LAST",$B3,$B3)} -> #N/A N/A | AH3: {=_xll.BDH(AH$2 & " US Equity","PX_LAST",$B3,$B3)} -> #N/A N/A | AI3: {=_xll.BDH(AI$2 & " US Equity","PX_LAST",$B3,$B3)} -> #N/A N/A | AJ3: {=_xll.BDH(AJ$2 & " US Equity","PX_LAST",$B3,$B3)} -> #N/A N/A | AK3: {=_xll.BDH(AK$2 & " US Equity","PX_LAST",$B3,$B3)} -> #N/A N/A | AL3: {=_xll.BDH(AL$2 & " US Equity","PX_LAST",$B3,$B3)} -> #N/A N/A | AM3: {=_xll.BDH(AM$2 & " US Equity","PX_LAST",$B3,$B3)} -> #N/A N/A | ... AW3: {=_xll.BDH(AW$2 & " US Equity","PX_LAST",$B3,$B3)} -> #N/A N/A
B4: 45902 | C4: {=_xll.BDH(C$2 & " US Equity","PX_LAST",$B4,$B4)} -> 224.18 | D4: {=_xll.BDH(D$2 & " PE Equity","PX_LAST",$B4,$B4)} -> 3.99 | E4: {=_xll.BDH(E$2 & " PE Equity","PX_LAST",$B4,$B4)} -> 1.74 | F4: {=_xll.BDH(F$2 & " PE Equity","PX_LAST",$B4,$B4)} -> 2.55 | G4: {=_xll.BDH(G$2 & " US Equity","PX_LAST",$B4,$B4)} -> 20.79 | H4: {=_xll.BDH(H$2 & " PE Equity","PX_LAST",$B4,$B4)} -> 3.47 | I4: {=_xll.BDH(I$2 & " US Equity","PX_LAST",$B4,$B4)} -> 40.98 | J4: {=_xll.BDH(J$2 & " US Equity","PX_LAST",$B4,$B4)} -> 6.8058 | K4: {=_xll.BDH(K$2 & " US Equity","PX_LAST",$B4,$B4)} -> 47.02 | L4: {=_xll.BDH(L$2 & " US Equity","PX_LAST",$B4,$B4)} -> 49.82 | M4: {=_xll.BDH(M$2 & " US Equity","PX_LAST",$B4,$B4)} -> 260.11 | N4: {=_xll.BDH(N$2 & " US Equity","PX_LAST",$B4,$B4)} -> 32.97 | O4: {=_xll.BDH(O$2 & " US Equity","PX_LAST",$B4,$B4)} -> 29 | P4: {=_xll.BDH(P$2 & " US Equity","PX_LAST",$B4,$B4)} -> 14.16 | ... Z4: {=_xll.BDH(Z$2 & " US Equity","PX_LAST",$B4,$B4)} -> 286.48 | AA4: {=_xll.BDH(AA$2 & " PE Equity","PX_LAST",$B4,$B4)} -> 0.384 | AB4: {=_xll.BDH(AB$2 & " PE Equity","PX_LAST",$B4,$B4)} -> 27.94 | AC4: {=_xll.BDH(AC$2 & " US Equity","PX_LAST",$B4,$B4)} -> 67.81 | AD4: {=_xll.BDH(AD$2 & " US Equity","PX_LAST",$B4,$B4)} -> 640.27 | AE4: {=_xll.BDH(AE$2 & " PE Equity","PX_LAST",$B4,$B4)} -> #N/A Connection | AF4: {=_xll.BDH(AF$2 & " US Equity","PX_LAST",$B4,$B4)} -> 51.593 | AG4: {=_xll.BDH(AG$2 & " US Equity","PX_LAST",$B4,$B4)} -> 13.1551 | AH4: {=_xll.BDH(AH$2 & " US Equity","PX_LAST",$B4,$B4)} -> 565.62 | AI4: {=_xll.BDH(AI$2 & " US Equity","PX_LAST",$B4,$B4)} -> 107.41 | AJ4: {=_xll.BDH(AJ$2 & " US Equity","PX_LAST",$B4,$B4)} -> 118.27 | AK4: {=_xll.BDH(AK$2 & " US Equity","PX_LAST",$B4,$B4)} -> 115.005 | AL4: {=_xll.BDH(AL$2 & " US Equity","PX_LAST",$B4,$B4)} -> 225.34 | AM4: {=_xll.BDH(AM$2 & " US Equity","PX_LAST",$B4,$B4)} -> 43.54 | ... AW4: {=_xll.BDH(AW$2 & " US Equity","PX_LAST",$B4,$B4)} -> 138.74
B5: 45903 | C5: {=_xll.BDH(C$2 & " US Equity","PX_LAST",$B5,$B5)} -> 225.34 | D5: {=_xll.BDH(D$2 & " PE Equity","PX_LAST",$B5,$B5)} -> 4 | E5: {=_xll.BDH(E$2 & " PE Equity","PX_LAST",$B5,$B5)} -> 1.66 | F5: {=_xll.BDH(F$2 & " PE Equity","PX_LAST",$B5,$B5)} -> 2.56 | G5: {=_xll.BDH(G$2 & " US Equity","PX_LAST",$B5,$B5)} -> 20.25 | H5: {=_xll.BDH(H$2 & " PE Equity","PX_LAST",$B5,$B5)} -> 3.48 | I5: {=_xll.BDH(I$2 & " US Equity","PX_LAST",$B5,$B5)} -> 41.57 | J5: {=_xll.BDH(J$2 & " US Equity","PX_LAST",$B5,$B5)} -> 6.7379 | K5: {=_xll.BDH(K$2 & " US Equity","PX_LAST",$B5,$B5)} -> 47.05 | L5: {=_xll.BDH(L$2 & " US Equity","PX_LAST",$B5,$B5)} -> 50.01 | M5: {=_xll.BDH(M$2 & " US Equity","PX_LAST",$B5,$B5)} -> 261.56 | N5: {=_xll.BDH(N$2 & " US Equity","PX_LAST",$B5,$B5)} -> 32.99 | O5: {=_xll.BDH(O$2 & " US Equity","PX_LAST",$B5,$B5)} -> 28.99 | P5: {=_xll.BDH(P$2 & " US Equity","PX_LAST",$B5,$B5)} -> 14.2 | ... Z5: {=_xll.BDH(Z$2 & " US Equity","PX_LAST",$B5,$B5)} -> 286.43 | AA5: {=_xll.BDH(AA$2 & " PE Equity","PX_LAST",$B5,$B5)} -> 0.4 | AB5: {=_xll.BDH(AB$2 & " PE Equity","PX_LAST",$B5,$B5)} -> 27.9 | AC5: {=_xll.BDH(AC$2 & " US Equity","PX_LAST",$B5,$B5)} -> 67.64 | AD5: {=_xll.BDH(AD$2 & " US Equity","PX_LAST",$B5,$B5)} -> 643.74 | AE5: {=_xll.BDH(AE$2 & " PE Equity","PX_LAST",$B5,$B5)} -> #N/A Connection | AF5: {=_xll.BDH(AF$2 & " US Equity","PX_LAST",$B5,$B5)} -> 51.6447 | AG5: {=_xll.BDH(AG$2 & " US Equity","PX_LAST",$B5,$B5)} -> 13.1886 | AH5: {=_xll.BDH(AH$2 & " US Equity","PX_LAST",$B5,$B5)} -> 570.07 | AI5: {=_xll.BDH(AI$2 & " US Equity","PX_LAST",$B5,$B5)} -> 107.43 | AJ5: {=_xll.BDH(AJ$2 & " US Equity","PX_LAST",$B5,$B5)} -> 117.38 | AK5: {=_xll.BDH(AK$2 & " US Equity","PX_LAST",$B5,$B5)} -> 115.47 | AL5: {=_xll.BDH(AL$2 & " US Equity","PX_LAST",$B5,$B5)} -> 225.99 | AM5: {=_xll.BDH(AM$2 & " US Equity","PX_LAST",$B5,$B5)} -> 44.555 | ... AW5: {=_xll.BDH(AW$2 & " US Equity","PX_LAST",$B5,$B5)} -> 134.83
B6: 45904 | C6: {=_xll.BDH(C$2 & " US Equity","PX_LAST",$B6,$B6)} -> 225.28 | D6: {=_xll.BDH(D$2 & " PE Equity","PX_LAST",$B6,$B6)} -> 4 | E6: {=_xll.BDH(E$2 & " PE Equity","PX_LAST",$B6,$B6)} -> #N/A N/A | F6: {=_xll.BDH(F$2 & " PE Equity","PX_LAST",$B6,$B6)} -> 2.54 | G6: {=_xll.BDH(G$2 & " US Equity","PX_LAST",$B6,$B6)} -> 19.84 | H6: {=_xll.BDH(H$2 & " PE Equity","PX_LAST",$B6,$B6)} -> 3.48 | I6: {=_xll.BDH(I$2 & " US Equity","PX_LAST",$B6,$B6)} -> 42.02 | J6: {=_xll.BDH(J$2 & " US Equity","PX_LAST",$B6,$B6)} -> 6.7864 | K6: {=_xll.BDH(K$2 & " US Equity","PX_LAST",$B6,$B6)} -> 47.48 | L6: {=_xll.BDH(L$2 & " US Equity","PX_LAST",$B6,$B6)} -> 49.85 | M6: {=_xll.BDH(M$2 & " US Equity","PX_LAST",$B6,$B6)} -> 259.98 | N6: {=_xll.BDH(N$2 & " US Equity","PX_LAST",$B6,$B6)} -> 33.37 | O6: {=_xll.BDH(O$2 & " US Equity","PX_LAST",$B6,$B6)} -> 29.17 | P6: {=_xll.BDH(P$2 & " US Equity","PX_LAST",$B6,$B6)} -> 14.33 | ... Z6: {=_xll.BDH(Z$2 & " US Equity","PX_LAST",$B6,$B6)} -> 289.86 | AA6: {=_xll.BDH(AA$2 & " PE Equity","PX_LAST",$B6,$B6)} -> 0.4 | AB6: {=_xll.BDH(AB$2 & " PE Equity","PX_LAST",$B6,$B6)} -> 27.5 | AC6: {=_xll.BDH(AC$2 & " US Equity","PX_LAST",$B6,$B6)} -> 68.25 | AD6: {=_xll.BDH(AD$2 & " US Equity","PX_LAST",$B6,$B6)} -> 649.12 | AE6: {=_xll.BDH(AE$2 & " PE Equity","PX_LAST",$B6,$B6)} -> #N/A Connection | AF6: {=_xll.BDH(AF$2 & " US Equity","PX_LAST",$B6,$B6)} -> 51.7739 | AG6: {=_xll.BDH(AG$2 & " US Equity","PX_LAST",$B6,$B6)} -> 13.3765 | AH6: {=_xll.BDH(AH$2 & " US Equity","PX_LAST",$B6,$B6)} -> 575.23 | AI6: {=_xll.BDH(AI$2 & " US Equity","PX_LAST",$B6,$B6)} -> 108.84 | AJ6: {=_xll.BDH(AJ$2 & " US Equity","PX_LAST",$B6,$B6)} -> 118.81 | AK6: {=_xll.BDH(AK$2 & " US Equity","PX_LAST",$B6,$B6)} -> 117.58 | AL6: {=_xll.BDH(AL$2 & " US Equity","PX_LAST",$B6,$B6)} -> 235.68 | AM6: {=_xll.BDH(AM$2 & " US Equity","PX_LAST",$B6,$B6)} -> 45.76 | ... AW6: {=_xll.BDH(AW$2 & " US Equity","PX_LAST",$B6,$B6)} -> 137.35
